Workbook
Name \A: #REF!
Name \B: #REF!
Name \BUR: #REF!
Name \C: #REF!
Name \D: #REF!
Name \F: #REF!
Name \FOREX: #REF!
Name \g: #REF!
Name \M: #REF!
Name \O: #REF!
Name \Q: #REF!
Name \R: #REF!
Name \s: #REF!
Name \T: #REF!
Name \X: #REF!
Name \Z: #REF!
Name _1: #REF!
Name _1_????????: #REF!
Name _10A6: [3]LOAN!#REF!
Name _10A6: #REF!
Name _11: #REF!
Name _11A66: [3]LOAN!#REF!
Name _11A66: #REF!
Name _12EFF: #REF!
Name _13PORTFO: #REF!
Name _2_????????????12: #REF!
Name _2000_0630100000_Umsatzerlöse: #REF!
Name _2000_0630160000_Konsortialanteile_Umsatzerlöse__UPL__verb.: #REF!
Name _2000_0630160100_Untervergabe_an_verb._Unternehmen__UPL: #REF!
Name _2000_0630180000_Umsatzerlöse__UPL: #REF!
Name _2000_0630440000_Auftragskosten__UKV: #REF!
Name _2000_0630440010_Auftragskosten_des_Umsatzes__UKV: #REF!
Name _2000_0630440020_Konsortialanteile_in_Auftragskosten__UKV: #REF!
Name _2000_0630440021_Untervergabe_an_verb._Unternehmen__UKV: #REF!
Name _2000_0630440030_Auftragskosten_des_Umsatzes_für_ZG__UKV: #REF!
Name _2000_0630450000_Auflösung_Rückst._Nachlaufkosten__UKV: #REF!
Name _2000_0630460000_Deckungsabweichung__UKV: #REF!
Name _2000_0630470000_Garantiekosten__UKV: #REF!
Name _2000_0630480000_Forschung_und_Entwicklung__UKV: #REF!
Name _2000_0630490000_Vertriebskosten__UKV: #REF!
Name _2000_0630500000_Sonstige_betriebliche_Erträge: #REF!
Name _2000_0630500010_Ertr.aus_dem_Abgang_von_Gegenst._des_AV: #REF!
Name _2000_0630500022_Ertr.aus_der_Zuschreib._zu_Gegenst._d._Finanz: #REF!
Name _2000_0630500023_Ertr.aus_der_Zuschreib._Goodwill: #REF!
Name _2000_0630500030_Ertr.aus_der_Aufl.von_Rückstellungen: #REF!
Name _2000_0630500040_Ertr.aus_der_Aufl.des_Sonderp.mit_Rueckl.Ant.: #REF!
Name _2000_0630500300_Ertr.aus_dem_Abgang_von_Gegenst._des_AV__UKV: #REF!
Name _2000_0630500305_Ertr.aus_dem_Abgang_von_Finanzanlagever._UKV: #REF!
Name _2000_0630500310_Ertr.aus_Wertaufholung_Anlageverm.__UKV: #REF!
Name _2000_0630500320_Garantierückstellung_Auflösung__UKV: #REF!
Name _2000_0630500330_Auflösung_sonstige_Rückstellung__UKV: #REF!
Name _2000_0630500335_Auflösung_poc_Rückstellung__UKV: #REF!
Name _2000_0630500340_Kursgewinne_Ford._und_Verb._UKV: #REF!
Name _2000_0630500350_WB_auf_Forderungen_Auflösung__UKV: #REF!
Name _2000_0630500360_Ertr._aus_Änderungen_Bewertungsmeth.__UKV: #REF!
Name _2000_0630500370_Management_fees_Ertrag__UKV: #REF!
Name _2000_0630500380_Ertr._aus_Umlagen__UKV: #REF!
Name _2000_0630500390_Umlagen_KöSt.__Solz__UKV: #REF!
Name _2000_0630500400_Umlagen_Gewerbeertragsteuer__UKV: #REF!
Name _2000_0630500410_Umlagen_im_Ausland_gez._Steuern__UKV: #REF!

Sheet SCB-CP
A1: S.No. | B1: WBS | C1: SO | D1: Qty | E1: Equipment Name | F1: scope | G1: Planner | H1: Zero Date | I1: CDD | J1: Equipment Weight in KG | K1: Manufacturing Planned Hours | P1: Manufacturing Utilization Hours | U1: Available Capacity SCB | Z1: Actual Capacity SCB | AG1: Actual Welding | AV1: Actual Milling Machining | BK1: Actual CNC Lathe Machining | BZ1: Actual Assembly
K2: Welding | L2: Milling Machining | M2: CNC Lathe Machining | N2: Assembly | O2: Total Hours | P2: Welding | Q2: Milling Machining | R2: CNC Lathe Machining | S2: Assembly | T2: Total Hours | U2: Welding | V2: Milling Machining | W2: CNC Lathe Machining | X2: Assembly | Y2: Total Hours | Z2: Welding | AA2: Milling Machining | AB2: CNC Lathe Machining | AC2: Assembly | AD2: Total Hours | AE2: Order | AF2: Category | AG2: 46174 | AH2: 46204 | AI2: 46235 | AJ2: 46266 | AK2: 46296 | AL2: 46327 | AM2: 46357 | AN2: 46388 | AO2: 46419 | AP2: 46447 | AQ2: 46478 | AR2: 46508 | AS2: Total | AT2: Order | AU2: Category | AV2: 46174 | AW2: 46204 | AX2: 46235 | AY2: 46266 | AZ2: 46296 | BA2: 46327 | BB2: 46357 | BC2: 46388 | BD2: 46419 | BE2: 46447 | BF2: 46478 | BG2: 46508 | BH2: Total | BI2: Order | BJ2: Category | BK2: 46174 | BL2: 46204 | BM2: 46235 | BN2: 46266 | BO2: 46296 | BP2: 46327 | BQ2: 46357 | BR2: 46388 | BS2: 46419 | BT2: 46447 | BU2: 46478 | BV2: 46508 | BW2: Total | BX2: Order | BY2: Category | BZ2: 46174 | CA2: 46204 | CB2: 46235 | CC2: 46266 | CD2: 46296 | CE2: 46327 | CF2: 46357 | CG2: 46388 | CH2: 46419 | CI2: 46447 | CJ2: 46478 | CK2: 46508 | CL2: Total | CM2: Diff-FAB | CN2: Diff-MILL | CO2: Diff-LATHE | CP2: Diff-ASS
A3: 1 | B3: C00450X010.99.1000 | E3: Turret Base | F3: NA | G3: AVIJIT SAHA | H3: 44671 | I3: 44895 | J3: 9700 | K3: 1308 | L3: 125 | O3: =SUM(K3:N3) -> 1433 | P3: 2295.14 | Q3: 64 | R3: 57.2 | T3: =SUM(P3:S3) -> 2416.34 | U3: =K3-P3 -> -987.14 | V3: =L3-Q3 -> 61 | W3: =M3-R3 -> -57.2 | X3: =N3-S3 -> 0 | Y3: =SUM(U3:X3) -> -983.34 | Z3: =AS3 -> 0 | AA3: =BH3 -> 0 | AB3: =BW3 -> 0 | AC3: =CL3 -> 0 | AD3: =SUM(Z3:AC3) -> 0 | AE3: Contract | AF3: DIRECT | AS3: =SUM(AG3:AR3) -> 0 | AT3: Contract | AU3: DIRECT | BH3: =SUM(AV3:BG3) -> 0 | BI3: Contract | BJ3: DIRECT | BW3: =SUM(BK3:BV3) -> 0 | BX3: Contract | BY3: DIRECT | CL3: =SUM(BZ3:CK3) -> 0 | CM3: =U3-Z3 -> -987.14 | CN3: =V3-AA3 -> 61 | CO3: =W3-AB3 -> -57.2 | CP3: =X3-AC3 -> 0
A4: 2 | B4: C00525X010.1000 | E4: LADLE TURRET WEDGE TYPE 1 | F4: NA | G4: AVIJIT SAHA | H4: 44805 | I4: 44834 | K4: 300 | O4: =SUM(K4:N4) -> 300 | P4: 4 | Q4: 73.8 | T4: =SUM(P4:S4) -> 77.8 | U4: =K4-P4 -> 296 | V4: =L4-Q4 -> -73.8 | W4: =M4-R4 -> 0 | X4: =N4-S4 -> 0 | Y4: =SUM(U4:X4) -> 222.2 | Z4: =AS4 -> 0 | AA4: =BH4 -> 0 | AB4: =BW4 -> 0 | AC4: =CL4 -> 0 | AD4: =SUM(Z4:AC4) -> 0 | AE4: Contract | AF4: DIRECT | AS4: =SUM(AG4:AR4) -> 0 | AT4: Contract | AU4: DIRECT | BH4: =SUM(AV4:BG4) -> 0 | BI4: Contract | BJ4: DIRECT | BW4: =SUM(BK4:BV4) -> 0 | BX4: Contract | BY4: DIRECT | CL4: =SUM(BZ4:CK4) -> 0 | CM4: =U4-Z4 -> 296 | CN4: =V4-AA4 -> -73.8 | CO4: =W4-AB4 -> 0 | CP4: =X4-AC4 -> 0
A5: 3 | B5: A03394M220.20.10.10P1000 | C5: WBS | E5: Converter vessel | F5: NA | G5: KRISHNASIS | H5: 45054 | I5: 45381 | J5: 22000 | K5: 8000 | L5: 54 | O5: =SUM(K5:N5) -> 8054 | P5: 7108.64 | Q5: 52 | R5: 102.9 | T5: =SUM(P5:S5) -> 7263.54 | U5: =K5-P5 -> 891.36 | V5: =L5-Q5 -> 2 | W5: =M5-R5 -> -102.9 | X5: =N5-S5 -> 0 | Y5: =SUM(U5:X5) -> 790.46 | Z5: =AS5 -> 407 | AA5: =BH5 -> 0 | AB5: =BW5 -> 0 | AC5: =CL5 -> 0 | AD5: =SUM(Z5:AC5) -> 407 | AE5: OTH | AF5: WBS | AG5: 407 | AS5: =SUM(AG5:AR5) -> 407 | AT5: OTH | AU5: WBS | BH5: =SUM(AV5:BG5) -> 0 | BI5: OTH | BJ5: WBS | BW5: =SUM(BK5:BV5) -> 0 | BX5: OTH | BY5: WBS | CL5: =SUM(BZ5:CK5) -> 0 | CM5: =U5-Z5 -> 484.36 | CN5: =V5-AA5 -> 2 | CO5: =W5-AB5 -> -102.9 | CP5: =X5-AC5 -> 0
A6: 4 | B6: A03520M220.20.20P0110 | C6: WBS | E6: Blowing lance body | F6: NA | G6: Kameshwaran | H6: 45427 | J6: 5000 | K6: 1024 | M6: 55 | O6: =SUM(K6:N6) -> 1079 | P6: 1391 | Q6: 8.5 | T6: =SUM(P6:S6) -> 1399.5 | U6: =K6-P6 -> -367 | V6: =L6-Q6 -> -8.5 | W6: =M6-R6 -> 55 | X6: =N6-S6 -> 0 | Y6: =SUM(U6:X6) -> -320.5 | Z6: =AS6 -> 0 | AA6: =BH6 -> 0 | AB6: =BW6 -> 0 | AC6: =CL6 -> 0 | AD6: =SUM(Z6:AC6) -> 0 | AE6: OTH | AF6: WBS | AS6: =SUM(AG6:AR6) -> 0 | AT6: OTH | AU6: WBS | BH6: =SUM(AV6:BG6) -> 0 | BI6: OTH | BJ6: WBS | BW6: =SUM(BK6:BV6) -> 0 | BX6: OTH | BY6: WBS | CL6: =SUM(BZ6:CK6) -> 0 | CM6: =U6-Z6 -> -367 | CN6: =V6-AA6 -> -8.5 | CO6: =W6-AB6 -> 55 | CP6: =X6-AC6 -> 0
A7: 5 | B7: A03520M220.85P1000 | C7: WBS | E7: operational change parts oxygen lance | G7: Kameshwaran | H7: 45427 | J7: 5000 | K7: 1024 | L7: 55 | O7: =SUM(K7:N7) -> 1079 | P7: 1497 | R7: 5 | T7: =SUM(P7:S7) -> 1502 | U7: =K7-P7 -> -473 | V7: =L7-Q7 -> 55 | W7: =M7-R7 -> -5 | X7: =N7-S7 -> 0 | Y7: =SUM(U7:X7) -> -423 | Z7: =AS7 -> 200 | AA7: =BH7 -> 55 | AB7: =BW7 -> 0 | AC7: =CL7 -> 0 | AD7: =SUM(Z7:AC7) -> 255 | AE7: OTH | AF7: WBS | AG7: 200 | AS7: =SUM(AG7:AR7) -> 200 | AT7: OTH | AU7: WBS | AV7: 55 | BH7: =SUM(AV7:BG7) -> 55 | BI7: OTH | BJ7: WBS | BW7: =SUM(BK7:BV7) -> 0 | BX7: OTH | BY7: WBS | CL7: =SUM(BZ7:CK7) -> 0 | CM7: =U7-Z7 -> -673 | CN7: =V7-AA7 -> 0 | CO7: =W7-AB7 -> -5 | CP7: =X7-AC7 -> 0
A8: 6 | B8: A03520M220.40.10.50P1010 | C8: WBS | E8: Electrode Arms - PCA | F8: NA only ass | G8: Ravi Ranjan | I8: 45657 | J8: 15890 | K8: 5960 | L8: 280 | M8: 150 | N8: 300 | O8: =SUM(K8:N8) -> 6690 | P8: 8422 | Q8: 474.2 | R8: 303 | T8: =SUM(P8:S8) -> 9199.2 | U8: =K8-P8 -> -2462 | V8: =L8-Q8 -> -194.2 | W8: =M8-R8 -> -153 | X8: =N8-S8 -> 300 | Y8: =SUM(U8:X8) -> -2509.2 | Z8: =AS8 -> 0 | AA8: =BH8 -> 0 | AB8: =BW8 -> 0 | AC8: =CL8 -> 0 | AD8: =SUM(Z8:AC8) -> 0 | AE8: OTH | AF8: WBS | AS8: =SUM(AG8:AR8) -> 0 | AT8: OTH | AU8: WBS | BH8: =SUM(AV8:BG8) -> 0 | BI8: OTH | BJ8: WBS | BW8: =SUM(BK8:BV8) -> 0 | BX8: OTH | BY8: WBS | CL8: =SUM(BZ8:CK8) -> 0 | CM8: =U8-Z8 -> -2462 | CN8: =V8-AA8 -> -194.2 | CO8: =W8-AB8 -> -153 | CP8: =X8-AC8 -> 300
A9: 7 | B9: A03520M220.86.30P0100 | C9: WBS | E9: Electrode Clamp Assbly-Spare | F9: NA only ass | G9: Ravi Ranjan | I9: 45657 | J9: 732 | O9: =SUM(K9:N9) -> 0 | T9: =SUM(P9:S9) -> 0 | U9: =K9-P9 -> 0 | V9: =L9-Q9 -> 0 | W9: =M9-R9 -> 0 | X9: =N9-S9 -> 0 | Y9: =SUM(U9:X9) -> 0 | Z9: =AS9 -> 0 | AA9: =BH9 -> 0 | AB9: =BW9 -> 0 | AC9: =CL9 -> 0 | AD9: =SUM(Z9:AC9) -> 0 | AE9: OTH | AF9: WBS | AS9: =SUM(AG9:AR9) -> 0 | AT9: OTH | AU9: WBS | BH9: =SUM(AV9:BG9) -> 0 | BI9: OTH | BJ9: WBS | BW9: =SUM(BK9:BV9) -> 0 | BX9: OTH | BY9: WBS | CL9: =SUM(BZ9:CK9) -> 0 | CM9: =U9-Z9 -> 0 | CN9: =V9-AA9 -> 0 | CO9: =W9-AB9 -> 0 | CP9: =X9-AC9 -> 0
A10: 8 | B10: A03520M220.86.30P0200 | C10: WBS | E10: Contact Pad- Spare | F10: NA | G10: Ravi Ranjan | I10: 45657 | J10: 236 | O10: =SUM(K10:N10) -> 0 | T10: =SUM(P10:S10) -> 0 | U10: =K10-P10 -> 0 | V10: =L10-Q10 -> 0 | W10: =M10-R10 -> 0 | X10: =N10-S10 -> 0 | Y10: =SUM(U10:X10) -> 0 | Z10: =AS10 -> 0 | AA10: =BH10 -> 0 | AB10: =BW10 -> 0 | AC10: =CL10 -> 0 | AD10: =SUM(Z10:AC10) -> 0 | AE10: OTH | AF10: WBS | AS10: =SUM(AG10:AR10) -> 0 | AT10: OTH | AU10: WBS | BH10: =SUM(AV10:BG10) -> 0 | BI10: OTH | BJ10: WBS | BW10: =SUM(BK10:BV10) -> 0 | BX10: OTH | BY10: WBS | CL10: =SUM(BZ10:CK10) -> 0 | CM10: =U10-Z10 -> 0 | CN10: =V10-AA10 -> 0 | CO10: =W10-AB10 -> 0 | CP10: =X10-AC10 -> 0
A11: 9 | B11: A03508M120.10.12P3000 A03508M120.96.01P2000 | C11: WBS | E11: TUYERE STOCK (MAIN -24+SPARE -5) MOUNTING JIG REFRACTORY JIG DOWNLEG & ELBOW-BLOWPIPE DISMANTLING DEVICE | F11: NA | G11: Ravi Ranjan | H11: 45463 | I11: 45736 | J11: 60000 | K11: 6000 | L11: 172 | O11: =SUM(K11:N11) -> 6172 | P11: 8267.67 | Q11: 24 | R11: 231 | S11: 7 | T11: =SUM(P11:S11) -> 8529.67 | U11: =K11-P11 -> -2267.67 | V11: =L11-Q11 -> 148 | W11: =M11-R11 -> -231 | X11: =N11-S11 -> -7 | Y11: =SUM(U11:X11) -> -2357.67 | Z11: =AS11 -> 0 | AA11: =BH11 -> 0 | AB11: =BW11 -> 0 | AC11: =CL11 -> 0 | AD11: =SUM(Z11:AC11) -> 0 | AE11: OTH | AF11: WBS | AS11: =SUM(AG11:AR11) -> 0 | AT11: OTH | AU11: WBS | BH11: =SUM(AV11:BG11) -> 0 | BI11: OTH | BJ11: WBS | BW11: =SUM(BK11:BV11) -> 0 | BX11: OTH | BY11: WBS | CL11: =SUM(BZ11:CK11) -> 0 | CM11: =U11-Z11 -> -2267.67 | CN11: =V11-AA11 -> 148 | CO11: =W11-AB11 -> -231 | CP11: =X11-AC11 -> -7
A12: 10 | B12: ET560067341 | C12: 72003581 | E12: FINAL MACHINING & ASSEMBLY OF WORK ROLL CHOCKS - 2 SETS | F12: NA | G12: Ravi Ranjan | H12: 44748 | I12: 45026 | L12: 450 | N12: 200 | O12: =SUM(K12:N12) -> 650 | P12: 204 | Q12: 1462.8 | R12: 133.4 | S12: 838 | T12: =SUM(P12:S12) -> 2638.2 | U12: =K12-P12 -> -204 | V12: =L12-Q12 -> -1012.8 | W12: =M12-R12 -> -133.4 | X12: =N12-S12 -> -638 | Y12: =SUM(U12:X12) -> -1988.2 | Z12: =AS12 -> 0 | AA12: =BH12 -> 0 | AB12: =BW12 -> 0 | AC12: =CL12 -> 0 | AD12: =SUM(Z12:AC12) -> 0 | AE12: OTH | AF12: SERVICE | AS12: =SUM(AG12:AR12) -> 0 | AT12: OTH | AU12: SERVICE | BH12: =SUM(AV12:BG12) -> 0 | BI12: OTH | BJ12: SERVICE | BW12: =SUM(BK12:BV12) -> 0 | BX12: OTH | BY12: SERVICE | CL12: =SUM(BZ12:CK12) -> 0 | CM12: =U12-Z12 -> -204 | CN12: =V12-AA12 -> -1012.8 | CO12: =W12-AB12 -> -133.4 | CP12: =X12-AC12 -> -638
A13: 11 | B13: ET560065841 | C13: 72003480 | E13: Mandrel Spares | F13: NA | G13: Ravi Ranjan | H13: 44687 | I13: 45949 | O13: =SUM(K13:N13) -> 0 | R13: 3 | S13: 1000 | T13: =SUM(P13:S13) -> 1003 | U13: =K13-P13 -> 0 | V13: =L13-Q13 -> 0 | W13: =M13-R13 -> -3 | X13: =N13-S13 -> -1000 | Y13: =SUM(U13:X13) -> -1003 | Z13: =AS13 -> 0 | AA13: =BH13 -> 0 | AB13: =BW13 -> 0 | AC13: =CL13 -> 0 | AD13: =SUM(Z13:AC13) -> 0 | AE13: OTH | AF13: SERVICE | AS13: =SUM(AG13:AR13) -> 0 | AT13: OTH | AU13: SERVICE | BH13: =SUM(AV13:BG13) -> 0 | BI13: OTH | BJ13: SERVICE | BW13: =SUM(BK13:BV13) -> 0 | BX13: OTH | BY13: SERVICE | CL13: =SUM(BZ13:CK13) -> 0 | CM13: =U13-Z13 -> 0 | CN13: =V13-AA13 -> 0 | CO13: =W13-AB13 -> -3 | CP13: =X13-AC13 -> -1000
A14: 12 | B14: ET560076197 | C14: 72004059 | E14: Mandrel Spares -Segments | F14: NA | G14: Ravi Ranjan | H14: 44925 | I14: 45949 | S14: 520 | T14: =SUM(P14:S14) -> 520 | U14: =K14-P14 -> 0 | V14: =L14-Q14 -> 0 | W14: =M14-R14 -> 0 | X14: =N14-S14 -> -520 | Y14: =SUM(U14:X14) -> -520 | Z14: =AS14 -> 0 | AA14: =BH14 -> 0 | AB14: =BW14 -> 0 | AC14: =CL14 -> 0 | AD14: =SUM(Z14:AC14) -> 0 | AE14: OTH | AF14: SERVICE | AS14: =SUM(AG14:AR14) -> 0 | AT14: OTH | AU14: SERVICE | BH14: =SUM(AV14:BG14) -> 0 | BI14: OTH | BJ14: SERVICE | BW14: =SUM(BK14:BV14) -> 0 | BX14: OTH | BY14: SERVICE | CL14: =SUM(BZ14:CK14) -> 0 | CM14: =U14-Z14 -> 0 | CN14: =V14-AA14 -> 0 | CO14: =W14-AB14 -> 0 | CP14: =X14-AC14 -> -520
A15: 13 | B15: ET430084421 | C15: 72004601 | E15: FIXED HOOD LD2 | G15: Rejeesh | H15: 45394 | I15: 45777 | J15: 35000 | K15: 8000 | M15: 30 | O15: =SUM(K15:N15) -> 8030 | P15: 2311 | T15: =SUM(P15:S15) -> 2311 | U15: =K15-P15 -> 5689 | V15: =L15-Q15 -> 0 | W15: =M15-R15 -> 30 | X15: =N15-S15 -> 0 | Y15: =SUM(U15:X15) -> 5719 | Z15: =AS15 -> 8689 | AA15: =BH15 -> 0 | AB15: =BW15 -> 30 | AC15: =CL15 -> 0 | AD15: =SUM(Z15:AC15) -> 8719 | AE15: OTH | AF15: SERVICE | AG15: 2173 | AH15: 2172 | AI15: 2172 | AJ15: 2172 | AS15: =SUM(AG15:AR15) -> 8689 | AT15: OTH | AU15: SERVICE | BH15: =SUM(AV15:BG15) -> 0 | BI15: OTH | BJ15: SERVICE | BK15: 30 | BW15: =SUM(BK15:BV15) -> 30 | BX15: OTH | BY15: SERVICE | CL15: =SUM(BZ15:CK15) -> 0 | CM15: =U15-Z15 -> -3000 | CN15: =V15-AA15 -> 0 | CO15: =W15-AB15 -> 0 | CP15: =X15-AC15 -> 0
A16: 14 | B16: ET430095286 | C16: 72005231 | E16: SEGMENT 9_14 | F16: NA only ass | G16: Amulya Jena | H16: 45407 | I16: 45777 | J16: 60000 | K16: 6652 | L16: 1440 | N16: 2500 | O16: =SUM(K16:N16) -> 10592 | P16: 8434.45 | Q16: 777 | R16: 597 | S16: 12 | T16: =SUM(P16:S16) -> 9820.45 | U16: =K16-P16 -> -1782.45 | V16: =L16-Q16 -> 663 | W16: =M16-R16 -> -597 | X16: =N16-S16 -> 2488 | Y16: =SUM(U16:X16) -> 771.55 | Z16: =AS16 -> 0 | AA16: =BH16 -> 0 | AB16: =BW16 -> 0 | AC16: =CL16 -> 2488 | AD16: =SUM(Z16:AC16) -> 2488 | AE16: OTH | AF16: SERVICE | AS16: =SUM(AG16:AR16) -> 0 | AT16: OTH | AU16: SERVICE | BH16: =SUM(AV16:BG16) -> 0 | BI16: OTH | BJ16: SERVICE | BW16: =SUM(BK16:BV16) -> 0 | BX16: OTH | BY16: SERVICE | CA16: 1244 | CB16: 1244 | CL16: =SUM(BZ16:CK16) -> 2488 | CM16: =U16-Z16 -> -1782.45 | CN16: =V16-AA16 -> 663 | CO16: =W16-AB16 -> -597 | CP16: =X16-AC16 -> 0
A17: 15 | B17: ET460096489 | C17: 72005405 | E17: COOLING STACK 1 to 5 & COVER | F17: NA | G17: Rejeesh | H17: 45470 | I17: 45816 | J17: 40000 | K17: 12000 | M17: 330 | O17: =SUM(K17:N17) -> 12330 | P17: 4616 | T17: =SUM(P17:S17) -> 4616 | U17: =K17-P17 -> 7384 | V17: =L17-Q17 -> 0 | W17: =M17-R17 -> 330 | X17: =N17-S17 -> 0 | Y17: =SUM(U17:X17) -> 7714 | Z17: =AS17 -> 0 | AA17: =BH17 -> 0 | AB17: =BW17 -> 0 | AC17: =CL17 -> 0 | AD17: =SUM(Z17:AC17) -> 0 | AE17: OTH | AF17: SERVICE | AS17: =SUM(AG17:AR17) -> 0 | AT17: OTH | AU17: SERVICE | BH17: =SUM(AV17:BG17) -> 0 | BI17: OTH | BJ17: SERVICE | BW17: =SUM(BK17:BV17) -> 0 | BX17: OTH | BY17: SERVICE | CL17: =SUM(BZ17:CK17) -> 0 | CM17: =U17-Z17 -> 7384 | CN17: =V17-AA17 -> 0 | CO17: =W17-AB17 -> 330 | CP17: =X17-AC17 -> 0
A18: 16 | B18: ET460096654 | C18: 72005582 | E18: EAF TILTING PLATFORM & SUBSTRUCTRES | G18: Amulya Jena | H18: 45558 | I18: 45930 | J18: 30000 | K18: 9759.08 | L18: 140 | M18: 100 | O18: =SUM(K18:N18) -> 9999.08 | T18: =SUM(P18:S18) -> 0 | U18: =K18-P18 -> 9759.08 | V18: =L18-Q18 -> 140 | W18: =M18-R18 -> 100 | X18: =N18-S18 -> 0 | Y18: =SUM(U18:X18) -> 9999.08 | Z18: =AS18 -> 9759 | AA18: =BH18 -> 140 | AB18: =BW18 -> 100 | AC18: =CL18 -> 0 | AD18: =SUM(Z18:AC18) -> 9999 | AE18: OTH | AF18: SERVICE | AG18: 3253 | AH18: 3253 | AI18: 3253 | AS18: =SUM(AG18:AR18) -> 9759 | AT18: OTH | AU18: SERVICE | AV18: 140 | BH18: =SUM(AV18:BG18) -> 140 | BI18: OTH | BJ18: SERVICE | BK18: 100 | BW18: =SUM(BK18:BV18) -> 100 | BX18: OTH | BY18: SERVICE | CL18: =SUM(BZ18:CK18) -> 0 | CM18: =U18-Z18 -> 0.08 | CN18: =V18-AA18 -> 0 | CO18: =W18-AB18 -> 0 | CP18: =X18-AC18 -> 0
A19: 17 | B19: ET300093198 | C19: 72005103 | E19: Main cylinder with platten with bush | F19: NA | G19: SHASHIKUMAR | H19: 45604 | J19: 4000 | K19: 1231 | L19: 196 | O19: =SUM(K19:N19) -> 1427 | P19: 1687.3 | Q19: 416.4 | R19: 68.1 | T19: =SUM(P19:S19) -> 2171.8 | U19: =K19-P19 -> -456.3 | V19: =L19-Q19 -> -220.4 | W19: =M19-R19 -> -68.1 | X19: =N19-S19 -> 0 | Y19: =SUM(U19:X19) -> -744.8 | Z19: =AS19 -> 0 | AA19: =BH19 -> 0 | AB19: =BW19 -> 0 | AC19: =CL19 -> 0 | AD19: =SUM(Z19:AC19) -> 0 | AE19: OTH | AF19: SERVICE | AS19: =SUM(AG19:AR19) -> 0 | AT19: OTH | AU19: SERVICE | BH19: =SUM(AV19:BG19) -> 0 | BI19: OTH | BJ19: SERVICE | BW19: =SUM(BK19:BV19) -> 0 | BX19: OTH | BY19: SERVICE | CL19: =SUM(BZ19:CK19) -> 0 | CM19: =U19-Z19 -> -456.3 | CN19: =V19-AA19 -> -220.4 | CO19: =W19-AB19 -> -68.1 | CP19: =X19-AC19 -> 0
A20: 18 | B20: ET430096681 | C20: 72005606 | E20: MOLD OSCILLATION UNIT & MOLD CARRIER | G20: Kameshwaran | H20: 45562 | I20: 46067 | J20: 20000 | K20: 3630 | L20: 280 | M20: 130 | N20: 550 | O20: =SUM(K20:N20) -> 4590 | P20: 4067.17 | Q20: 238.3 | R20: 76.55 | T20: =SUM(P20:S20) -> 4382.02 | U20: =K20-P20 -> -437.17 | V20: =L20-Q20 -> 41.7 | W20: =M20-R20 -> 53.45 | X20: =N20-S20 -> 550 | Y20: =SUM(U20:X20) -> 207.98 | Z20: =AS20 -> 0 | AA20: =BH20 -> 42 | AB20: =BW20 -> 53 | AC20: =CL20 -> 550 | AD20: =SUM(Z20:AC20) -> 645 | AE20: OTH | AF20: SERVICE | AS20: =SUM(AG20:AR20) -> 0 | AT20: OTH | AU20: SERVICE | AV20: 42 | BH20: =SUM(AV20:BG20) -> 42 | BI20: OTH | BJ20: SERVICE | BK20: 53 | BW20: =SUM(BK20:BV20) -> 53 | BX20: OTH | BY20: SERVICE | BZ20: 550 | CL20: =SUM(BZ20:CK20) -> 550 | CM20: =U20-Z20 -> -437.17 | CN20: =V20-AA20 -> -0.3 | CO20: =W20-AB20 -> 0.45 | CP20: =X20-AC20 -> 0
A21: 19 | B21: A03533M120.10.12P3000 A03533M120.80.01P3020 A03533M120.80.01P4000 | C21: WBS | D21: 52 | E21: Tuyere Stock BF 2Yr Spare - Tuyere stock BF - Comm Spare - Tuyere stock | F21: PANKAJ | G21: Ravi Ranjan | H21: 45492 | I21: 45736 | J21: 180000 | K21: 16422 | M21: 678 | O21: =SUM(K21:N21) -> 17100 | P21: 10925 | Q21: 13 | R21: 139.05 | T21: =SUM(P21:S21) -> 11077.05 | U21: =K21-P21 -> 5497 | V21: =L21-Q21 -> -13 | W21: =M21-R21 -> 538.95 | X21: =N21-S21 -> 0 | Y21: =SUM(U21:X21) -> 6022.95 | Z21: =AS21 -> 5497 | AA21: =BH21 -> 0 | AB21: =BW21 -> 539 | AC21: =CL21 -> 0 | AD21: =SUM(Z21:AC21) -> 6036 | AE21: OTH | AF21: WBS | AG21: 1833 | AH21: 1832 | AI21: 1832 | AS21: =SUM(AG21:AR21) -> 5497 | AT21: OTH | AU21: WBS | BH21: =SUM(AV21:BG21) -> 0 | BI21: OTH | BJ21: WBS | BK21: 539 | BW21: =SUM(BK21:BV21) -> 539 | BX21: OTH | BY21: WBS | CL21: =SUM(BZ21:CK21) -> 0 | CM21: =U21-Z21 -> 0 | CN21: =V21-AA21 -> -13 | CO21: =W21-AB21 -> -0.05 | CP21: =X21-AC21 -> 0
A22: 20 | B22: A03533M120.80.01P3005 | C22: WBS | E22: BF 2Yr Spare - Centering and Wear device | F22: NA | G22: SANGRAM SWAIN | H22: 45429 | O22: =SUM(K22:N22) -> 0 | T22: =SUM(P22:S22) -> 0 | U22: =K22-P22 -> 0 | V22: =L22-Q22 -> 0 | W22: =M22-R22 -> 0 | X22: =N22-S22 -> 0 | Y22: =SUM(U22:X22) -> 0 | Z22: =AS22 -> 0 | AA22: =BH22 -> 0 | AB22: =BW22 -> 0 | AC22: =CL22 -> 0 | AD22: =SUM(Z22:AC22) -> 0 | AE22: OTH | AF22: WBS | AS22: =SUM(AG22:AR22) -> 0 | AT22: OTH | AU22: WBS | BH22: =SUM(AV22:BG22) -> 0 | BI22: OTH | BJ22: WBS | BW22: =SUM(BK22:BV22) -> 0 | BX22: OTH | BY22: WBS | CL22: =SUM(BZ22:CK22) -> 0 | CM22: =U22-Z22 -> 0 | CN22: =V22-AA22 -> 0 | CO22: =W22-AB22 -> 0 | CP22: =X22-AC22 -> 0
A23: 21 | B23: A03520M220.20.70.44P0500 | C23: WBS | D23: 1 | E23: INTERCONNECTING PIPING | F23: NA | G23: Kameshwaran | H23: 45513 | K23: 132 | M23: 26 | O23: =SUM(K23:N23) -> 158 | P23: 141 | R23: 3 | T23: =SUM(P23:S23) -> 144 | U23: =K23-P23 -> -9 | V23: =L23-Q23 -> 0 | W23: =M23-R23 -> 23 | X23: =N23-S23 -> 0 | Y23: =SUM(U23:X23) -> 14 | Z23: =AS23 -> 0 | AA23: =BH23 -> 0 | AB23: =BW23 -> 0 | AC23: =CL23 -> 0 | AD23: =SUM(Z23:AC23) -> 0 | AE23: OTH | AF23: WBS | AS23: =SUM(AG23:AR23) -> 0 | AT23: OTH | AU23: WBS | BH23: =SUM(AV23:BG23) -> 0 | BI23: OTH | BJ23: WBS | BW23: =SUM(BK23:BV23) -> 0 | BX23: OTH | BY23: WBS | CL23: =SUM(BZ23:CK23) -> 0 | CM23: =U23-Z23 -> -9 | CN23: =V23-AA23 -> 0 | CO23: =W23-AB23 -> 23 | CP23: =X23-AC23 -> 0
A24: 22 | B24: A03520M220.35.20.40P1100 | C24: WBS | D24: 2 | E24: TEEMING LADLE TRANSFER CAR AT LF | F24: NA | G24: Ravi Ranjan | H24: 45548 | J24: 85000 | K24: 5185 | L24: 672 | M24: 160 | N24: 750 | O24: =SUM(K24:N24) -> 6767 | P24: 5830.686 | Q24: 658.5 | R24: 575.5 | T24: =SUM(P24:S24) -> 7064.686 | U24: =K24-P24 -> -645.686 | V24: =L24-Q24 -> 13.5 | W24: =M24-R24 -> -415.5 | X24: =N24-S24 -> 750 | Y24: =SUM(U24:X24) -> -297.686 | Z24: =AS24 -> 0 | AA24: =BH24 -> 0 | AB24: =BW24 -> 0 | AC24: =CL24 -> 750 | AD24: =SUM(Z24:AC24) -> 750 | AE24: OTH | AF24: WBS | AS24: =SUM(AG24:AR24) -> 0 | AT24: OTH | AU24: WBS | BH24: =SUM(AV24:BG24) -> 0 | BI24: OTH | BJ24: WBS | BW24: =SUM(BK24:BV24) -> 0 | BX24: OTH | BY24: WBS | BZ24: 750 | CL24: =SUM(BZ24:CK24) -> 750 | CM24: =U24-Z24 -> -645.686 | CN24: =V24-AA24 -> 13.5 | CO24: =W24-AB24 -> -415.5 | CP24: =X24-AC24 -> 0
A25: 23 | B25: A03613M120.25P1500 | C25: WBS | D25: 1 | E25: GOGGLE VALVE ND 1600 SLIDE TYPE | G25: SANGRAM SWAIN | H25: 45575 | J25: 7000 | K25: 2411.88 | L25: 680 | M25: 200 | N25: 800 | O25: =SUM(K25:N25) -> 4091.88 | P25: 3501.01 | Q25: 350.2 | R25: 298 | T25: =SUM(P25:S25) -> 4149.21 | U25: =K25-P25 -> -1089.13 | V25: =L25-Q25 -> 329.8 | W25: =M25-R25 -> -98 | X25: =N25-S25 -> 800 | Y25: =SUM(U25:X25) -> -57.33 | Z25: =AS25 -> 0 | AA25: =BH25 -> 330 | AB25: =BW25 -> 0 | AC25: =CL25 -> 800 | AD25: =SUM(Z25:AC25) -> 1130 | AE25: OTH | AF25: WBS | AS25: =SUM(AG25:AR25) -> 0 | AT25: OTH | AU25: WBS | AV25: 165 | AW25: 165 | BH25: =SUM(AV25:BG25) -> 330 | BI25: OTH | BJ25: WBS | BW25: =SUM(BK25:BV25) -> 0 | BX25: OTH | BY25: WBS | BZ25: 800 | CL25: =SUM(BZ25:CK25) -> 800 | CM25: =U25-Z25 -> -1089.13 | CN25: =V25-AA25 -> -0.2 | CO25: =W25-AB25 -> -98 | CP25: =X25-AC25 -> 0
A26: 24 | B26: A03613M120.25P1525 | C26: WBS | D26: 1 | E26: COMBUSTION GAS ENRICHMENT GOGGLE VALVE DN 450 | F26: NA | G26: SANGRAM SWAIN | H26: 45575 | J26: 15000 | K26: 1896 | L26: 188 | N26: 800 | O26: =SUM(K26:N26) -> 2884 | P26: 919 | Q26: 169.6 | R26: 207 | T26: =SUM(P26:S26) -> 1295.6 | U26: =K26-P26 -> 977 | V26: =L26-Q26 -> 18.4 | W26: =M26-R26 -> -207 | X26: =N26-S26 -> 800 | Y26: =SUM(U26:X26) -> 1588.4 | Z26: =AS26 -> 0 | AA26: =BH26 -> 0 | AB26: =BW26 -> 0 | AC26: =CL26 -> 0 | AD26: =SUM(Z26:AC26) -> 0 | AE26: OTH | AF26: WBS | AS26: =SUM(AG26:AR26) -> 0 | AT26: OTH | AU26: WBS | BH26: =SUM(AV26:BG26) -> 0 | BI26: OTH | BJ26: WBS | BW26: =SUM(BK26:BV26) -> 0 | BX26: OTH | BY26: WBS | CL26: =SUM(BZ26:CK26) -> 0 | CM26: =U26-Z26 -> 977 | CN26: =V26-AA26 -> 18.4 | CO26: =W26-AB26 -> -207 | CP26: =X26-AC26 -> 800
A27: 25 | B27: 8564 | C27: SO | D27: 2 | E27: TWIN LADLE FURNACE WATER COOLED ROOF | F27: APEX | G27: Rejeesh | H27: 45623 | J27: 14000 | K27: 5732 | L27: 80 | O27: =SUM(K27:N27) -> 5812 | T27: =SUM(P27:S27) -> 0 | U27: =K27-P27 -> 5732 | V27: =L27-Q27 -> 80 | W27: =M27-R27 -> 0 | X27: =N27-S27 -> 0 | Y27: =SUM(U27:X27) -> 5812 | Z27: =AS27 -> 0 | AA27: =BH27 -> 0 | AB27: =BW27 -> 0 | AC27: =CL27 -> 0 | AD27: =SUM(Z27:AC27) -> 0 | AE27: OTH | AF27: SERVICE | AS27: =SUM(AG27:AR27) -> 0 | AT27: OTH | AU27: SERVICE | BH27: =SUM(AV27:BG27) -> 0 | BI27: OTH | BJ27: SERVICE | BW27: =SUM(BK27:BV27) -> 0 | BX27: OTH | BY27: SERVICE | CL27: =SUM(BZ27:CK27) -> 0 | CM27: =U27-Z27 -> 5732 | CN27: =V27-AA27 -> 80 | CO27: =W27-AB27 -> 0 | CP27: =X27-AC27 -> 0
A28: 26 | B28: A03520M220.86.40P0200 | C28: WBS | E28: SPARES FOR LADLE TRANSFER CARS-GEARBOX,COUPLINGS,BRAKE,BEARING,DRIVE WHEEL ASSLY | F28: NA | G28: Ravi Ranjan | H28: 45631 | K28: 150 | N28: 70 | O28: =SUM(K28:N28) -> 220 | T28: =SUM(P28:S28) -> 0 | U28: =K28-P28 -> 150 | V28: =L28-Q28 -> 0 | W28: =M28-R28 -> 0 | X28: =N28-S28 -> 70 | Y28: =SUM(U28:X28) -> 220 | Z28: =AS28 -> 0 | AA28: =BH28 -> 0 | AB28: =BW28 -> 0 | AC28: =CL28 -> 70 | AD28: =SUM(Z28:AC28) -> 70 | AE28: OTH | AF28: WBS | AS28: =SUM(AG28:AR28) -> 0 | AT28: OTH | AU28: WBS | BH28: =SUM(AV28:BG28) -> 0 | BI28: OTH | BJ28: WBS | BW28: =SUM(BK28:BV28) -> 0 | BX28: OTH | BY28: WBS | CB28: 70 | CL28: =SUM(BZ28:CK28) -> 70 | CM28: =U28-Z28 -> 150 | CN28: =V28-AA28 -> 0 | CO28: =W28-AB28 -> 0 | CP28: =X28-AC28 -> 0
A29: 27 | B29: S000611SMP.LSH.LAS.LAL1 S000611SMP.LSH.LAS.LAL2 S000611SMP.LSH.LAS.LAL3 S000611SMP.LSH.LAS.LAL4 S000611SMP.LSH.LAS.LAL5 S000611SMP.LSH.LAS.LAL6 | C29: 9149 | D29: 6 | E29: STEEL TEEMING LADLE | G29: KRISHNASIS | H29: 45625 | I29: 45991 | J29: 300000 | K29: 29215 | L29: 420 | O29: =SUM(K29:N29) -> 29635 | P29: 28222 | Q29: 376 | R29: 371 | S29: 591 | T29: =SUM(P29:S29) -> 29560 | U29: =K29-P29 -> 993 | V29: =L29-Q29 -> 44 | W29: =M29-R29 -> -371 | X29: =N29-S29 -> -591 | Y29: =SUM(U29:X29) -> 75 | Z29: =AS29 -> 993 | AA29: =BH29 -> 44 | AB29: =BW29 -> 0 | AC29: =CL29 -> 160 | AD29: =SUM(Z29:AC29) -> 1197 | AE29: Contract | AF29: DIRECT | AG29: 496.5 | AH29: 496.5 | AS29: =SUM(AG29:AR29) -> 993 | AT29: Contract | AU29: DIRECT | AV29: 44 | BH29: =SUM(AV29:BG29) -> 44 | BI29: Contract | BJ29: DIRECT | BW29: =SUM(BK29:BV29) -> 0 | BX29: Contract | BY29: DIRECT | BZ29: 160 | CL29: =SUM(BZ29:CK29) -> 160 | CM29: =U29-Z29 -> 0 | CN29: =V29-AA29 -> 0 | CO29: =W29-AB29 -> -371 | CP29: =X29-AC29 -> -751
A30: 28 | B30: 9179 | C30: SO | D30: 2 | E30: FINAL MACHINING OF EDGER HOUSING CASSETTE ASSEMBLY WITH LINERS | F30: Sanad | G30: SHASHIKUMAR | H30: 45636 | J30: 14000 | K30: 28 | L30: 400 | N30: 150 | O30: =SUM(K30:N30) -> 578 | T30: =SUM(P30:S30) -> 0 | U30: =K30-P30 -> 28 | V30: =L30-Q30 -> 400 | W30: =M30-R30 -> 0 | X30: =N30-S30 -> 150 | Y30: =SUM(U30:X30) -> 578 | Z30: =AS30 -> 0 | AA30: =BH30 -> 0 | AB30: =BW30 -> 0 | AC30: =CL30 -> 0 | AD30: =SUM(Z30:AC30) -> 0 | AE30: OTH | AF30: SERVICE | AS30: =SUM(AG30:AR30) -> 0 | AT30: OTH | AU30: SERVICE | BH30: =SUM(AV30:BG30) -> 0 | BI30: OTH | BJ30: SERVICE | BW30: =SUM(BK30:BV30) -> 0 | BX30: OTH | BY30: SERVICE | CL30: =SUM(BZ30:CK30) -> 0 | CM30: =U30-Z30 -> 28 | CN30: =V30-AA30 -> 400 | CO30: =W30-AB30 -> 0 | CP30: =X30-AC30 -> 150
A31: 29 | B31: A03520M220.55.40.20P0100 | C31: WBS | D31: 1 | E31: LADLE TILTER | G31: AMULYA JENA | H31: 45684 | I31: 45991 | J31: 30000 | K31: 5120 | L31: 280 | N31: 200 | O31: =SUM(K31:N31) -> 5600 | P31: 4485.02 | Q31: 141.7 | R31: 73.5 | T31: =SUM(P31:S31) -> 4700.22 | U31: =K31-P31 -> 634.98 | V31: =L31-Q31 -> 138.3 | W31: =M31-R31 -> -73.5 | X31: =N31-S31 -> 200 | Y31: =SUM(U31:X31) -> 899.78 | Z31: =AS31 -> 635 | AA31: =BH31 -> 138 | AB31: =BW31 -> 0 | AC31: =CL31 -> 200 | AD31: =SUM(Z31:AC31) -> 973 | AE31: OTH | AF31: WBS | AG31: 300 | AH31: 335 | AS31: =SUM(AG31:AR31) -> 635 | AT31: OTH | AU31: WBS | AV31: 138 | BH31: =SUM(AV31:BG31) -> 138 | BI31: OTH | BJ31: WBS | BW31: =SUM(BK31:BV31) -> 0 | BX31: OTH | BY31: WBS | BZ31: 200 | CL31: =SUM(BZ31:CK31) -> 200 | CM31: =U31-Z31 -> -0.02 | CN31: =V31-AA31 -> 0.3 | CO31: =W31-AB31 -> -73.5 | CP31: =X31-AC31 -> 0
A32: 30 | B32: S000348RML.FMA.URM.CHO S000348RML.FMA.EDM.CHO | C32: 9227 | D32: 3 | E32: ROLL CHOCK ASSEMBLY UR/UF & EDGER | F32: NA only ass | G32: SHASHIKUMAR | H32: 45687 | I32: 45700 | L32: 140 | N32: 420 | O32: =SUM(K32:N32) -> 560 | P32: 3.5 | Q32: 116.5 | R32: 82.5 | S32: 985 | T32: =SUM(P32:S32) -> 1187.5 | U32: =K32-P32 -> -3.5 | V32: =L32-Q32 -> 23.5 | W32: =M32-R32 -> -82.5 | X32: =N32-S32 -> -565 | Y32: =SUM(U32:X32) -> -627.5 | Z32: =AS32 -> 0 | AA32: =BH32 -> 0 | AB32: =BW32 -> 0 | AC32: =CL32 -> 0 | AD32: =SUM(Z32:AC32) -> 0 | AE32: OTH | AF32: SERVICE | AS32: =SUM(AG32:AR32) -> 0 | AT32: OTH | AU32: SERVICE | BH32: =SUM(AV32:BG32) -> 0 | BI32: OTH | BJ32: SERVICE | BW32: =SUM(BK32:BV32) -> 0 | BX32: OTH | BY32: SERVICE | CL32: =SUM(BZ32:CK32) -> 0 | CM32: =U32-Z32 -> -3.5 | CN32: =V32-AA32 -> 23.5 | CO32: =W32-AB32 -> -82.5 | CP32: =X32-AC32 -> -565
A33: 31 | B33: ET760096764 | C33: 72005686 | D33: 1 | E33: SEGMENT 11 | G33: Kameshwaran | H33: 45688 | I33: 46081 | J33: 4784 | K33: 3925 | L33: 370 | M33: 380 | N33: 700 | O33: =SUM(K33:N33) -> 5375 | P33: 3965.25 | Q33: 295.6 | R33: 672.35 | S33: 90 | T33: =SUM(P33:S33) -> 5023.2 | U33: =K33-P33 -> -40.25 | V33: =L33-Q33 -> 74.4 | W33: =M33-R33 -> -292.35 | X33: =N33-S33 -> 610 | Y33: =SUM(U33:X33) -> 351.8 | Z33: =AS33 -> 0 | AA33: =BH33 -> 74 | AB33: =BW33 -> 0 | AC33: =CL33 -> 610 | AD33: =SUM(Z33:AC33) -> 684 | AE33: OTH | AF33: SERVICE | AS33: =SUM(AG33:AR33) -> 0 | AT33: OTH | AU33: SERVICE | AW33: 74 | BH33: =SUM(AV33:BG33) -> 74 | BI33: OTH | BJ33: SERVICE | BW33: =SUM(BK33:BV33) -> 0 | BX33: OTH | BY33: SERVICE | BZ33: 610 | CL33: =SUM(BZ33:CK33) -> 610 | CM33: =U33-Z33 -> -40.25 | CN33: =V33-AA33 -> 0.4 | CO33: =W33-AB33 -> -292.35 | CP33: =X33-AC33 -> 0
A34: 32 | B34: 12301 | C34: SO | D34: 1 | E34: SEGMENT 12 | F34: NA | G34: Kameshwaran | H34: 45700 | I34: 46038 | J34: 14000 | K34: 1450 | L34: 405 | N34: 700 | O34: =SUM(K34:N34) -> 2555 | P34: 1489 | Q34: 1090 | R34: 1243 | S34: 872 | T34: =SUM(P34:S34) -> 4694 | U34: =K34-P34 -> -39 | V34: =L34-Q34 -> -685 | W34: =M34-R34 -> -1243 | X34: =N34-S34 -> -172 | Y34: =SUM(U34:X34) -> -2139 | Z34: =AS34 -> 0 | AA34: =BH34 -> 0 | AB34: =BW34 -> 0 | AC34: =CL34 -> 0 | AD34: =SUM(Z34:AC34) -> 0 | AE34: Group | AF34: DIRECT | AS34: =SUM(AG34:AR34) -> 0 | AT34: Group | AU34: DIRECT | BH34: =SUM(AV34:BG34) -> 0 | BI34: Group | BJ34: DIRECT | BW34: =SUM(BK34:BV34) -> 0 | BX34: Group | BY34: DIRECT | CL34: =SUM(BZ34:CK34) -> 0 | CM34: =U34-Z34 -> -39 | CN34: =V34-AA34 -> -685 | CO34: =W34-AB34 -> -1243 | CP34: =X34-AC34 -> -172
A35: 33 | B35: 13827 | C35: SO | D35: 2 | E35: REFURBISHMENT OF DSITRIBUTION CHUITE | F35: NA | G35: SANGRAM SWAIN | H35: 45742 | I35: 45850 | J35: 7420 | K35: =84*2 -> 168 | L35: =64*2 -> 128 | N35: 480 | O35: =SUM(K35:N35) -> 776 | P35: 14 | Q35: 15 | R35: 23.7 | S35: 747 | T35: =SUM(P35:S35) -> 799.7 | U35: =K35-P35 -> 154 | V35: =L35-Q35 -> 113 | W35: =M35-R35 -> -23.7 | X35: =N35-S35 -> -267 | Y35: =SUM(U35:X35) -> -23.7 | Z35: =AS35 -> 0 | AA35: =BH35 -> 0 | AB35: =BW35 -> 0 | AC35: =CL35 -> 0 | AD35: =SUM(Z35:AC35) -> 0 | AE35: OTH | AF35: SERVICE | AS35: =SUM(AG35:AR35) -> 0 | AT35: OTH | AU35: SERVICE | BH35: =SUM(AV35:BG35) -> 0 | BI35: OTH | BJ35: SERVICE | BW35: =SUM(BK35:BV35) -> 0 | BX35: OTH | BY35: SERVICE | CL35: =SUM(BZ35:CK35) -> 0 | CM35: =U35-Z35 -> 154 | CN35: =V35-AA35 -> 113 | CO35: =W35-AB35 -> -23.7 | CP35: =X35-AC35 -> -267
A36: 34 | B36: 11649 | C36: SO | D36: 3 | E36: F1-F4 BUR CHANGE SLEDGE ASSEMBLY | F36: NA | G36: Kameshwaran | H36: 45740 | J36: 15469 | O36: =SUM(K36:N36) -> 0 | P36: 27.5 | Q36: 660 | R36: 98.3 | S36: 1 | T36: =SUM(P36:S36) -> 786.8 | U36: =K36-P36 -> -27.5 | V36: =L36-Q36 -> -660 | W36: =M36-R36 -> -98.3 | X36: =N36-S36 -> -1 | Y36: =SUM(U36:X36) -> -786.8 | Z36: =AS36 -> 0 | AA36: =BH36 -> 0 | AB36: =BW36 -> 0 | AC36: =CL36 -> 0 | AD36: =SUM(Z36:AC36) -> 0 | AE36: OTH | AF36: SERVICE | AS36: =SUM(AG36:AR36) -> 0 | AT36: OTH | AU36: SERVICE | BH36: =SUM(AV36:BG36) -> 0 | BI36: OTH | BJ36: SERVICE | BW36: =SUM(BK36:BV36) -> 0 | BX36: OTH | BY36: SERVICE | CL36: =SUM(BZ36:CK36) -> 0 | CM36: =U36-Z36 -> -27.5 | CN36: =V36-AA36 -> -660 | CO36: =W36-AB36 -> -98.3 | CP36: =X36-AC36 -> -1
A37: 35 | B37: 14904 | C37: SO | D37: 1 | E37: REFURBISHMENT OF DSITRIBUTION CHUTE MIDI L-3.6M | F37: NA | G37: SANGRAM SWAIN | H37: 45764 | I37: 46081 | J37: 1631 | K37: 84 | L37: 64 | N37: 240 | O37: =SUM(K37:N37) -> 388 | S37: 238 | T37: =SUM(P37:S37) -> 238 | U37: =K37-P37 -> 84 | V37: =L37-Q37 -> 64 | W37: =M37-R37 -> 0 | X37: =N37-S37 -> 2 | Y37: =SUM(U37:X37) -> 150 | Z37: =AS37 -> 0 | AA37: =BH37 -> 0 | AB37: =BW37 -> 0 | AC37: =CL37 -> 0 | AD37: =SUM(Z37:AC37) -> 0 | AE37: OTH | AF37: SERVICE | AS37: =SUM(AG37:AR37) -> 0 | AT37: OTH | AU37: SERVICE | BH37: =SUM(AV37:BG37) -> 0 | BI37: OTH | BJ37: SERVICE | BW37: =SUM(BK37:BV37) -> 0 | BX37: OTH | BY37: SERVICE | CL37: =SUM(BZ37:CK37) -> 0 | CM37: =U37-Z37 -> 84 | CN37: =V37-AA37 -> 64 | CO37: =W37-AB37 -> 0 | CP37: =X37-AC37 -> 2
A38: 36 | B38: 15031 | C38: SO | D38: 6 | E38: ECCENTRIC WHEL ASSEMBLY | F38: NA | G38: SHASHIKUMAR | H38: 45777 | I38: 46022 | J38: 4728 | N38: 300 | O38: =SUM(K38:N38) -> 300 | T38: =SUM(P38:S38) -> 0 | U38: =K38-P38 -> 0 | V38: =L38-Q38 -> 0 | W38: =M38-R38 -> 0 | X38: =N38-S38 -> 300 | Y38: =SUM(U38:X38) -> 300 | Z38: =AS38 -> 0 | AA38: =BH38 -> 0 | AB38: =BW38 -> 0 | AC38: =CL38 -> 0 | AD38: =SUM(Z38:AC38) -> 0 | AE38: OTH | AF38: SERVICE | AS38: =SUM(AG38:AR38) -> 0 | AT38: OTH | AU38: SERVICE | BH38: =SUM(AV38:BG38) -> 0 | BI38: OTH | BJ38: SERVICE | BW38: =SUM(BK38:BV38) -> 0 | BX38: OTH | BY38: SERVICE | CL38: =SUM(BZ38:CK38) -> 0 | CM38: =U38-Z38 -> 0 | CN38: =V38-AA38 -> 0 | CO38: =W38-AB38 -> 0 | CP38: =X38-AC38 -> 300
A39: 37 | B39: 15541 | C39: SO | D39: 5 | E39: DOWNLEG ARRANGEMENT | F39: NA | G39: SANGRAM SWAIN | H39: 45784 | I39: 46022 | J39: 5995 | K39: 400 | N39: 80 | O39: =SUM(K39:N39) -> 480 | P39: 501 | S39: 241 | T39: =SUM(P39:S39) -> 742 | U39: =K39-P39 -> -101 | V39: =L39-Q39 -> 0 | W39: =M39-R39 -> 0 | X39: =N39-S39 -> -161 | Y39: =SUM(U39:X39) -> -262 | Z39: =AS39 -> 0 | AA39: =BH39 -> 0 | AB39: =BW39 -> 0 | AC39: =CL39 -> 0 | AD39: =SUM(Z39:AC39) -> 0 | AE39: OTH | AF39: SERVICE | AS39: =SUM(AG39:AR39) -> 0 | AT39: OTH | AU39: SERVICE | BH39: =SUM(AV39:BG39) -> 0 | BI39: OTH | BJ39: SERVICE | BW39: =SUM(BK39:BV39) -> 0 | BX39: OTH | BY39: SERVICE | CL39: =SUM(BZ39:CK39) -> 0 | CM39: =U39-Z39 -> -101 | CN39: =V39-AA39 -> 0 | CO39: =W39-AB39 -> 0 | CP39: =X39-AC39 -> -161
A40: 38 | B40: 16262 | C40: SO | D40: =2+2+2+2 -> 8 | E40: CHASSIS FRAME | F40: HOLD | G40: AVIJIT SAHA | H40: 45793 | I40: 45961 | J40: 7424 | K40: 3910 | L40: 160 | O40: =SUM(K40:N40) -> 4070 | P40: 2243 | Q40: 25.33 | R40: 89 | S40: 35 | T40: =SUM(P40:S40) -> 2392.33 | U40: =K40-P40 -> 1667 | V40: =L40-Q40 -> 134.67 | W40: =M40-R40 -> -89 | X40: =N40-S40 -> -35 | Y40: =SUM(U40:X40) -> 1677.67 | Z40: =AS40 -> 0 | AA40: =BH40 -> 0 | AB40: =BW40 -> 0 | AC40: =CL40 -> 0 | AD40: =SUM(Z40:AC40) -> 0 | AE40: Contract | AF40: DIRECT | AS40: =SUM(AG40:AR40) -> 0 | AT40: Contract | AU40: DIRECT | BH40: =SUM(AV40:BG40) -> 0 | BI40: Contract | BJ40: DIRECT | BW40: =SUM(BK40:BV40) -> 0 | BX40: Contract | BY40: DIRECT | CL40: =SUM(BZ40:CK40) -> 0 | CM40: =U40-Z40 -> 1667 | CN40: =V40-AA40 -> 134.67 | CO40: =W40-AB40 -> -89 | CP40: =X40-AC40 -> -35
...

Sheet SUMMARY-CP
A1: SUMMARY
A2: Sl No | B2: Planned | C2: Total Planned Hour | D2: 46174 | E2: 46204 | F2: 46235 | G2: 46266 | H2: 46297 | I2: 46327 | J2: 46357 | K2: 46388 | L2: 46419 | M2: 46447 | N2: 46478 | O2: 46508
A3: 1.1 | B3: OTHERS ORDERS | C3: =SUM(D3:O3) -> 190236.5 | D3: =GETPIVOTDATA("Sum of Jun/26",Welding!$A$3,"Order","OTH") -> 30360.25 | E3: =GETPIVOTDATA("Sum of Jul/26",Welding!$A$3,"Order","OTH") -> 28711.75 | F3: =GETPIVOTDATA("Sum of Aug/26",Welding!$A$3,"Order","OTH") -> 28053.25 | G3: =GETPIVOTDATA("Sum of Sep/26",Welding!$A$3,"Order","OTH") -> 24906.25 | H3: =GETPIVOTDATA("Sum of oct/26",Welding!$A$3,"Order","OTH") -> 20174 | I3: =GETPIVOTDATA("Sum of Nov/26",Welding!$A$3,"Order","OTH") -> 17836 | J3: =GETPIVOTDATA("Sum of Dec/26",Welding!$A$3,"Order","OTH") -> 12591 | K3: =GETPIVOTDATA("Sum of Jan/27",Welding!$A$3,"Order","OTH") -> 9104 | L3: =GETPIVOTDATA("Sum of Feb/27",Welding!$A$3,"Order","OTH") -> 6350 | M3: =GETPIVOTDATA("Sum of Mar/27",Welding!$A$3,"Order","OTH") -> 4050 | N3: =GETPIVOTDATA("Sum of Apr/27",Welding!$A$3,"Order","OTH") -> 4050 | O3: =GETPIVOTDATA("Sum of May/27",Welding!$A$3,"Order","OTH") -> 4050
A4: 1.2 | B4: GROUP COMPANY | C4: =SUM(D4:O4) -> 122796 | D4: =GETPIVOTDATA("Sum of Jun/26",Welding!$A$3,"Order","Group") -> 14938.5 | E4: =GETPIVOTDATA("Sum of Jul/26",Welding!$A$3,"Order","Group") -> 15175.5 | F4: =GETPIVOTDATA("Sum of Aug/26",Welding!$A$3,"Order","Group") -> 14938.5 | G4: =GETPIVOTDATA("Sum of Sep/26",Welding!$A$3,"Order","Group") -> 16142.5 | H4: =GETPIVOTDATA("Sum of Oct/26",Welding!$A$3,"Order","Group") -> 20441.5 | I4: =GETPIVOTDATA("Sum of Nov/26",Welding!$A$3,"Order","Group") -> 21440.5 | J4: =GETPIVOTDATA("Sum of Dec/26",Welding!$A$3,"Order","Group") -> 9884 | K4: =GETPIVOTDATA("Sum of Jan/27",Welding!$A$3,"Order","Group") -> 9385 | L4: =GETPIVOTDATA("Sum of Feb/27",Welding!$A$3,"Order","Group") -> 450 | M4: =GETPIVOTDATA("Sum of Mar/27",Welding!$A$3,"Order","Group") -> 0 | N4: =GETPIVOTDATA("Sum of Apr/27",Welding!$A$3,"Order","Group") -> 0 | O4: =GETPIVOTDATA("Sum of May/27",Welding!$A$3,"Order","Group") -> 0
A5: 1.3 | B5: CONTRACT MANUFACTURING | C5: =SUM(D5:O5) -> 33631 | D5: =GETPIVOTDATA("Sum of Jun/26",Welding!$A$3,"Order","Contract") -> 4532.5 | E5: =GETPIVOTDATA("Sum of Jul/26",Welding!$A$3,"Order","Contract") -> 5139.5 | F5: =GETPIVOTDATA("Sum of Aug/26",Welding!$A$3,"Order","Contract") -> 4322 | G5: =GETPIVOTDATA("Sum of Sep/26",Welding!$A$3,"Order","Contract") -> 3569 | H5: =GETPIVOTDATA("Sum of Oct/26",Welding!$A$3,"Order","Contract") -> 3568 | I5: =GETPIVOTDATA("Sum of Nov/26",Welding!$A$3,"Order","Contract") -> 2500 | J5: =GETPIVOTDATA("Sum of Dec/26",Welding!$A$3,"Order","Contract") -> 2500 | K5: =GETPIVOTDATA("Sum of Jan/27",Welding!$A$3,"Order","Contract") -> 2500 | L5: =GETPIVOTDATA("Sum of Feb/27",Welding!$A$3,"Order","Contract") -> 2500 | M5: =GETPIVOTDATA("Sum of Mar/27",Welding!$A$3,"Order","Contract") -> 2500 | N5: =GETPIVOTDATA("Sum of Apr/27",Welding!$A$3,"Order","Contract") -> 0 | O5: =GETPIVOTDATA("Sum of May/27",Welding!$A$3,"Order","Contract") -> 0
A6: 1 | B6: TOTAL WELDING | C6: =SUM(C3:C5) -> 346663.5 | D6: =SUM(D3:D5) -> 49831.25 | E6: =SUM(E3:E5) -> 49026.75 | F6: =SUM(F3:F5) -> 47313.75 | G6: =SUM(G3:G5) -> 44617.75 | H6: =SUM(H3:H5) -> 44183.5 | I6: =SUM(I3:I5) -> 41776.5 | J6: =SUM(J3:J5) -> 24975 | ... O6: =SUM(O3:O5) -> 4050
A8: 2.1 | B8: OTHERS ORDERS | C8: =SUM(D8:O8) -> 29134.5 | D8: =Machining!B23 -> 5035 | E8: =Machining!C23 -> 2557.5 | F8: =Machining!D23 -> 4425 | G8: =Machining!E23 -> 3619 | H8: =Machining!F23 -> 5507 | I8: =Machining!G23 -> 3565 | J8: =Machining!H23 -> 2304 | K8: =Machining!I23 -> 1215 | ... O8: =Machining!M23 -> 0
A9: 2.2 | B9: TS | C9: =SUM(D9:O9) -> 30000 | D9: =Machining!B24 -> 1850 | E9: =Machining!C24 -> 2600 | F9: =Machining!D24 -> 2600 | G9: =Machining!E24 -> 1950 | H9: =Machining!F24 -> 1550 | I9: =Machining!G24 -> 2000 | J9: =Machining!H24 -> 2500 | K9: =Machining!I24 -> 2500 | ... O9: =Machining!M24 -> 4282
A10: 2.3 | B10: GROUP COMPANY | C10: =SUM(D10:O10) -> 5587 | D10: =Machining!B22 -> 327 | E10: =Machining!C22 -> 327 | F10: =Machining!D22 -> 652 | G10: =Machining!E22 -> 711 | H10: =Machining!F22 -> 418 | I10: =Machining!G22 -> 800 | J10: =Machining!H22 -> 842 | K10: =Machining!I22 -> 785 | ... O10: =Machining!M22 -> 0
A11: 2.4 | B11: CONTRACT MANUFACTURING | C11: =SUM(D11:O11) -> 3863 | D11: =Machining!B21 -> 1263 | E11: =Machining!C21 -> 1308 | F11: =Machining!D21 -> 467 | G11: =Machining!E21 -> 260 | H11: =Machining!F21 -> 160 | I11: =Machining!G21 -> 185 | J11: =Machining!H21 -> 110 | K11: =Machining!I21 -> 110 | ... O11: =Machining!M21 -> 0
A12: 2 | B12: TOTAL MACHINING | C12: =SUM(C8:C11) -> 68584.5 | D12: =SUM(D8:D11) -> 8475 | E12: =SUM(E8:E11) -> 6792.5 | F12: =SUM(F8:F11) -> 8144 | G12: =SUM(G8:G11) -> 6540 | H12: =SUM(H8:H11) -> 7635 | I12: =SUM(I8:I11) -> 6550 | J12: =SUM(J8:J11) -> 5756 | ... O12: =SUM(O8:O11) -> 4282
A14: 3.1 | B14: OTHERS ORDERS | C14: =SUM(D14:O14) -> 25176 | D14: =GETPIVOTDATA("Sum of Jun-26",Assembly!$A$3,"Order","OTH") -> 3308 | E14: =GETPIVOTDATA("Sum of JuL-26",Assembly!$A$3,"Order","OTH") -> 2224 | F14: =GETPIVOTDATA("Sum of Aug-26",Assembly!$A$3,"Order","OTH") -> 1928 | G14: =GETPIVOTDATA("Sum of Sep-26",Assembly!$A$3,"Order","OTH") -> 1754 | H14: =GETPIVOTDATA("Sum of oct-26",Assembly!$A$3,"Order","OTH") -> 2302 | I14: =GETPIVOTDATA("Sum of Nov-26",Assembly!$A$3,"Order","OTH") -> 3775 | J14: =GETPIVOTDATA("Sum of Dec-26",Assembly!$A$3,"Order","OTH") -> 4265 | K14: =GETPIVOTDATA("Sum of Jan-27",Assembly!$A$3,"Order","OTH") -> 3090 | L14: =GETPIVOTDATA("Sum of Feb-27",Assembly!$A$3,"Order","OTH") -> 1470 | M14: =GETPIVOTDATA("Sum of Mar-27",Assembly!$A$3,"Order","OTH") -> 1060 | N14: =GETPIVOTDATA("Sum of Apr-27",Assembly!$A$3,"Order","OTH") -> 0 | O14: =GETPIVOTDATA("Sum of May-27",Assembly!$A$3,"Order","OTH") -> 0
A15: 3.2 | B15: GROUP COMPANY | C15: =SUM(D15:O15) -> 780 | D15: =GETPIVOTDATA("Sum of Jun-26",Assembly!$A$3,"Order","Group") -> 0 | E15: =GETPIVOTDATA("Sum of Jul-26",Assembly!$A$3,"Order","Group") -> 0 | F15: =GETPIVOTDATA("Sum of Aug-26",Assembly!$A$3,"Order","Group") -> 0 | G15: =GETPIVOTDATA("Sum of Sep-26",Assembly!$A$3,"Order","Group") -> 0 | H15: =GETPIVOTDATA("Sum of Oct-26",Assembly!$A$3,"Order","Group") -> 450 | I15: =GETPIVOTDATA("Sum of Nov-26",Assembly!$A$3,"Order","Group") -> 0 | J15: =GETPIVOTDATA("Sum of Dec-26",Assembly!$A$3,"Order","Group") -> 0 | K15: =GETPIVOTDATA("Sum of Jan-27",Assembly!$A$3,"Order","Group") -> 0 | L15: =GETPIVOTDATA("Sum of Feb-27",Assembly!$A$3,"Order","Group") -> 170 | M15: =GETPIVOTDATA("Sum of Mar-27",Assembly!$A$3,"Order","Group") -> 160 | N15: =GETPIVOTDATA("Sum of Apr-27",Assembly!$A$3,"Order","Group") -> 0 | O15: =GETPIVOTDATA("Sum of May-27",Assembly!$A$3,"Order","Group") -> 0
A16: 3.3 | B16: CONTRACT MANUFACTURING | C16: =SUM(D16:O16) -> 4099 | D16: =GETPIVOTDATA("Sum of Jun-26",Assembly!$A$3,"Order","Contract") -> 1180 | E16: =GETPIVOTDATA("Sum of Jul-26",Assembly!$A$3,"Order","Contract") -> 1069 | F16: =GETPIVOTDATA("Sum of Aug-26",Assembly!$A$3,"Order","Contract") -> 0 | G16: =GETPIVOTDATA("Sum of Sep-26",Assembly!$A$3,"Order","Contract") -> 50 | H16: =GETPIVOTDATA("Sum of Oct-26",Assembly!$A$3,"Order","Contract") -> 300 | I16: =GETPIVOTDATA("Sum of Nov-26",Assembly!$A$3,"Order","Contract") -> 300 | J16: =GETPIVOTDATA("Sum of Dec-26",Assembly!$A$3,"Order","Contract") -> 300 | K16: =GETPIVOTDATA("Sum of Jan-27",Assembly!$A$3,"Order","Contract") -> 300 | L16: =GETPIVOTDATA("Sum of Feb-27",Assembly!$A$3,"Order","Contract") -> 300 | M16: =GETPIVOTDATA("Sum of Mar-27",Assembly!$A$3,"Order","Contract") -> 300 | N16: =GETPIVOTDATA("Sum of Apr-27",Assembly!$A$3,"Order","Contract") -> 0 | O16: =GETPIVOTDATA("Sum of May-27",Assembly!$A$3,"Order","Contract") -> 0
A17: 3.4 | B17: ASSEMBLY-Hydraulic Test Stand | C17: 60 | D17: 10 | E17: 10 | F17: 10 | G17: 10 | H17: 10 | I17: 10 | J17: 0 | K17: 0 | L17: 0 | M17: 0 | N17: 0 | O17: 0
A18: 3.5 | B18: TS | C18: =SUM(D18:O18) -> 1800 | D18: =GETPIVOTDATA("Sum of Jun-26",Assembly!$A$3,"Order","TS") -> 30 | E18: =GETPIVOTDATA("Sum of Jul-26",Assembly!$A$3,"Order","TS") -> 40 | F18: =GETPIVOTDATA("Sum of Aug-26",Assembly!$A$3,"Order","TS") -> 250 | G18: =GETPIVOTDATA("Sum of Sep-26",Assembly!$A$3,"Order","TS") -> 300 | H18: =GETPIVOTDATA("Sum of Oct-26",Assembly!$A$3,"Order","TS") -> 280 | I18: =GETPIVOTDATA("Sum of Nov-26",Assembly!$A$3,"Order","TS") -> 200 | J18: =GETPIVOTDATA("Sum of Dec-26",Assembly!$A$3,"Order","TS") -> 200 | K18: =GETPIVOTDATA("Sum of Jan-27",Assembly!$A$3,"Order","TS") -> 100 | L18: =GETPIVOTDATA("Sum of Feb-27",Assembly!$A$3,"Order","TS") -> 100 | M18: =GETPIVOTDATA("Sum of Mar-27",Assembly!$A$3,"Order","TS") -> 100 | N18: =GETPIVOTDATA("Sum of Apr-27",Assembly!$A$3,"Order","TS") -> 100 | O18: =GETPIVOTDATA("Sum of May-27",Assembly!$A$3,"Order","TS") -> 100
A19: 3.6 | B19: IRON MAKING | C19: =SUM(D19:O19) -> 13820 | D19: =GETPIVOTDATA("Sum of Jun-26",Assembly!$A$3,"Order","IRON MAKING") -> 900 | E19: =GETPIVOTDATA("Sum of Jul-26",Assembly!$A$3,"Order","IRON MAKING") -> 2200 | F19: =GETPIVOTDATA("Sum of Aug-26",Assembly!$A$3,"Order","IRON MAKING") -> 3350 | G19: =GETPIVOTDATA("Sum of Sep-26",Assembly!$A$3,"Order","IRON MAKING") -> 3500 | H19: =GETPIVOTDATA("Sum of Oct-26",Assembly!$A$3,"Order","IRON MAKING") -> 2200 | I19: =GETPIVOTDATA("Sum of Nov-26",Assembly!$A$3,"Order","IRON MAKING") -> 500 | J19: =GETPIVOTDATA("Sum of Dec-26",Assembly!$A$3,"Order","IRON MAKING") -> 0 | K19: =GETPIVOTDATA("Sum of Jan-27",Assembly!$A$3,"Order","IRON MAKING") -> 670 | L19: =GETPIVOTDATA("Sum of Feb-27",Assembly!$A$3,"Order","IRON MAKING") -> 500 | M19: =GETPIVOTDATA("Sum of Mar-27",Assembly!$A$3,"Order","IRON MAKING") -> 0 | N19: =GETPIVOTDATA("Sum of Apr-27",Assembly!$A$3,"Order","IRON MAKING") -> 0 | O19: =GETPIVOTDATA("Sum of May-27",Assembly!$A$3,"Order","IRON MAKING") -> 0
A20: 3 | B20: TOTAL ASSEMBLY | C20: =SUM(C14:C16,C17:C19) -> 45735 | D20: =SUM(D14:D16,D17:D19) -> 5428 | E20: =SUM(E14:E16,E17:E19) -> 5543 | F20: =SUM(F14:F16,F17:F19) -> 5538 | G20: =SUM(G14:G16,G17:G19) -> 5614 | H20: =SUM(H14:H16,H17:H19) -> 5542 | I20: =SUM(I14:I16,I17:I19) -> 4785 | J20: =SUM(J14:J16,J17:J19) -> 4765 | ... O20: =SUM(O14:O16,O17:O19) -> 100
A22: 4 | B22: SERVICE-ROLL REFURBISHMENT | C22: 15276 | D22: 1800 | E22: 1600 | F22: 1500 | G22: 1400 | H22: 1300 | I22: 1200 | J22: 1100 | K22: 1100 | L22: 1100 | M22: 1176 | N22: 1000 | O22: 1000
A23: 5 | B23: SERVICE-PLATING | C23: 10260 | D23: 1300 | E23: 1300 | F23: 1200 | G23: 1000 | H23: 1000 | I23: 890 | J23: 800 | K23: 700 | L23: 600 | M23: 500 | N23: 500 | O23: 470
B25: TOTAL MANUFACTRING | C25: =C6+C12+C20+C22+C23 -> 486519 | D25: =D6+D12+D20+D22+D23 -> 66834.25 | E25: =E6+E12+E20+E22+E23 -> 64262.25 | F25: =F6+F12+F20+F22+F23 -> 63695.75 | G25: =G6+G12+G20+G22+G23 -> 59171.75 | H25: =H6+H12+H20+H22+H23 -> 59660.5 | I25: =I6+I12+I20+I22+I23 -> 55201.5 | J25: =J6+J12+J20+J22+J23 -> 37396 | ... O25: =O6+O12+O20+O22+O23 -> 9902
A27: Sl No | B27: Available Capacity (NPK) | C27: Total Available Hour | D27: 46174 | E27: 46204 | F27: 46235 | G27: 46266 | H27: 46296 | I27: 46327 | J27: 46357 | K27: 46388 | L27: 46419 | M27: 46447 | N27: 46478 | O27: 46508
A28: 1.1 | B28: KHURDA-WELDING-SMI | C28: =SUM(D28:O28) -> 19367.917 | D28: =NPK!I2 -> 1591.8836 | E28: =NPK!J2 -> 1644.9464 | F28: =NPK!K2 -> 1644.9464 | G28: =NPK!L2 -> 1591.8836 | H28: =NPK!M2 -> 1644.9464 | I28: =NPK!N2 -> 1591.8836 | J28: =NPK!O2 -> 1644.9464 | K28: =NPK!D2 -> 1644.9464 | L28: =NPK!E2 -> 1485.758 | M28: =NPK!F2 -> 1644.9464 | N28: =NPK!G2 -> 1591.8836 | O28: =NPK!H2 -> 1644.9464
A29: 1.2 | B29: KHURDA-WELDING-LS | C29: =SUM(D29:O29) -> 261466.88 | D29: =NPK!I3 -> 21490.428 | E29: =NPK!J3 -> 22206.776 | F29: =NPK!K3 -> 22206.776 | G29: =NPK!L3 -> 21490.428 | H29: =NPK!M3 -> 22206.776 | I29: =NPK!N3 -> 21490.428 | J29: =NPK!O3 -> 22206.776 | K29: =NPK!D3 -> 22206.776 | L29: =NPK!E3 -> 20057.733 | M29: =NPK!F3 -> 22206.776 | N29: =NPK!G3 -> 21490.428 | O29: =NPK!H3 -> 22206.776
A30: 1.3 | B30: KHURDA-WELDING-JC | C30: =SUM(D30:O30) -> 180767.22 | D30: =NPK!I4 -> 14857.58 | E30: =NPK!J4 -> 15352.833 | F30: =NPK!K4 -> 15352.833 | G30: =NPK!L4 -> 14857.58 | H30: =NPK!M4 -> 15352.833 | I30: =NPK!N4 -> 14857.58 | J30: =NPK!O4 -> 15352.833 | K30: =NPK!D4 -> 15352.833 | L30: =NPK!E4 -> 13867.075 | M30: =NPK!F4 -> 15352.833 | N30: =NPK!G4 -> 14857.58 | O30: =NPK!H4 -> 15352.833
A31: 1.1-1.3 | B31: KHURDA-WELDING (SMI+LS+JC) | C31: =C28+C29+C30 -> 461602.02 | D31: =D28+D29+D30 -> 37939.892 | E31: =E28+E29+E30 -> 39204.555 | F31: =F28+F29+F30 -> 39204.555 | G31: =G28+G29+G30 -> 37939.892 | H31: =H28+H29+H30 -> 39204.555 | I31: =I28+I29+I30 -> 37939.892 | J31: =J28+J29+J30 -> 39204.555 | ... O31: =O28+O29+O30 -> 39204.555
A32: 1.4 | B32: MANCHESWAR-WELDING-JC | C32: =SUM(D32:O32) -> 140252.1 | D32: =NPK!I6 -> 11527.57 | E32: =NPK!J6 -> 11911.822 | F32: =NPK!K6 -> 11911.822 | G32: =NPK!L6 -> 11527.57 | H32: =NPK!M6 -> 11911.822 | I32: =NPK!N6 -> 11527.57 | J32: =NPK!O6 -> 11911.822 | K32: =NPK!D6 -> 11911.822 | L32: =NPK!E6 -> 10759.065 | M32: =NPK!F6 -> 11911.822 | N32: =NPK!G6 -> 11527.57 | O32: =NPK!H6 -> 11911.822
A33: 1.5 | B33: MANCHESWAR-WELDING-LS | C33: =SUM(D33:O33) -> 6233.4265 | D33: =NPK!I7 -> 512.33643 | E33: =NPK!J7 -> 529.41431 | F33: =NPK!K7 -> 529.41431 | G33: =NPK!L7 -> 512.33643 | H33: =NPK!M7 -> 529.41431 | I33: =NPK!N7 -> 512.33643 | J33: =NPK!O7 -> 529.41431 | K33: =NPK!D7 -> 529.41431 | L33: =NPK!E7 -> 478.18067 | M33: =NPK!F7 -> 529.41431 | N33: =NPK!G7 -> 512.33643 | O33: =NPK!H7 -> 529.41431
A34: 1.6 | B34: MANCHESWAR-WELDING-SMI | C34: =SUM(D34:O34) -> 1558.3566 | D34: =NPK!I8 -> 128.08411 | E34: =NPK!J8 -> 132.35358 | F34: =NPK!K8 -> 132.35358 | G34: =NPK!L8 -> 128.08411 | H34: =NPK!M8 -> 132.35358 | I34: =NPK!N8 -> 128.08411 | J34: =NPK!O8 -> 132.35358 | K34: =NPK!D8 -> 132.35358 | L34: =NPK!E8 -> 119.54517 | M34: =NPK!F8 -> 132.35358 | N34: =NPK!G8 -> 128.08411 | O34: =NPK!H8 -> 132.35358
A35: 1.7 | B35: MANCHESWAR-WELDING (SMI+LS+JC) | C35: =SUM(C32:C34) -> 148043.88 | D35: =SUM(D32:D34) -> 12167.99 | E35: =SUM(E32:E34) -> 12573.59 | F35: =SUM(F32:F34) -> 12573.59 | G35: =SUM(G32:G34) -> 12167.99 | H35: =SUM(H32:H34) -> 12573.59 | I35: =SUM(I32:I34) -> 12167.99 | J35: =SUM(J32:J34) -> 12573.59 | ... O35: =SUM(O32:O34) -> 12573.59
A36: 1 | B36: K & M - WELDING (TOTAL) | C36: =C31+C32+C34+C33 -> 609645.9 | D36: =D31+D32+D34+D33 -> 50107.882 | E36: =E31+E32+E34+E33 -> 51778.145 | F36: =F31+F32+F34+F33 -> 51778.145 | G36: =G31+G32+G34+G33 -> 50107.882 | H36: =H31+H32+H34+H33 -> 51778.145 | I36: =I31+I32+I34+I33 -> 50107.882 | J36: =J31+J32+J34+J33 -> 51778.145 | ... O36: =O31+O32+O34+O33 -> 51778.145
A38: 2 | B38: TOTAL MACHINE SHOP | C38: =SUM(D38:O38) -> 106306.03 | D38: =NPK!I11 -> 8737.4818 | E38: =NPK!J11 -> 9028.7312 | F38: =NPK!K11 -> 9028.7312 | G38: =NPK!L11 -> 8737.4818 | H38: =NPK!M11 -> 9028.7312 | I38: =NPK!N11 -> 8737.4818 | J38: =NPK!O11 -> 9028.7312 | K38: =NPK!D11 -> 9028.7312 | L38: =NPK!E11 -> 8154.983 | M38: =NPK!F11 -> 9028.7312 | N38: =NPK!G11 -> 8737.4818 | O38: =NPK!H11 -> 9028.7312
A40: 3.1 | B40: ASSEMBLY-SMI | C40: =SUM(D40:O40) -> 16496.625 | D40: =NPK!I13 -> 1355.887 | E40: =NPK!J13 -> 1401.0832 | F40: =NPK!K13 -> 1401.0832 | G40: =NPK!L13 -> 1355.887 | H40: =NPK!M13 -> 1401.0832 | I40: =NPK!N13 -> 1355.887 | J40: =NPK!O13 -> 1401.0832 | K40: =NPK!D13 -> 1401.0832 | L40: =NPK!E13 -> 1265.4945 | M40: =NPK!F13 -> 1401.0832 | N40: =NPK!G13 -> 1355.887 | O40: =NPK!H13 -> 1401.0832
A41: 3.2 | B41: ASSEMBLY-LS | C41: =SUM(D41:O41) -> 32993.25 | D41: =NPK!I14 -> 2711.774 | E41: =NPK!J14 -> 2802.1664 | F41: =NPK!K14 -> 2802.1664 | G41: =NPK!L14 -> 2711.774 | H41: =NPK!M14 -> 2802.1664 | I41: =NPK!N14 -> 2711.774 | J41: =NPK!O14 -> 2802.1664 | K41: =NPK!D14 -> 2802.1664 | L41: =NPK!E14 -> 2530.989 | M41: =NPK!F14 -> 2802.1664 | N41: =NPK!G14 -> 2711.774 | O41: =NPK!H14 -> 2802.1664
A42: 3.3 | B42: ASSEMBLY-JS | C42: =SUM(D42:O42) -> 16496.625 | D42: =NPK!I15 -> 1355.887 | E42: =NPK!J15 -> 1401.0832 | F42: =NPK!K15 -> 1401.0832 | G42: =NPK!L15 -> 1355.887 | H42: =NPK!M15 -> 1401.0832 | I42: =NPK!N15 -> 1355.887 | J42: =NPK!O15 -> 1401.0832 | K42: =NPK!D15 -> 1401.0832 | L42: =NPK!E15 -> 1265.4945 | M42: =NPK!F15 -> 1401.0832 | N42: =NPK!G15 -> 1355.887 | O42: =NPK!H15 -> 1401.0832
A43: 3 | B43: ASSEMBLY-MFG | C43: =C40+C41+C42 -> 65986.5 | D43: =D40+D41+D42 -> 5423.5479 | E43: =E40+E41+E42 -> 5604.3329 | F43: =F40+F41+F42 -> 5604.3329 | G43: =G40+G41+G42 -> 5423.5479 | H43: =H40+H41+H42 -> 5604.3329 | I43: =I40+I41+I42 -> 5423.5479 | J43: =J40+J41+J42 -> 5604.3329 | ... O43: =O40+O41+O42 -> 5604.3329
A45: 4 | B45: ROLL REFURBISHMENT | C45: =SUM(D45:O45) -> 27553.475 | D45: =NPK!I18 -> 2264.6692 | E45: =NPK!J18 -> 2340.1581 | F45: =NPK!K18 -> 2340.1581 | G45: =NPK!L18 -> 2264.6692 | H45: =NPK!M18 -> 2340.1581 | I45: =NPK!N18 -> 2264.6692 | J45: =NPK!O18 -> 2340.1581 | K45: =NPK!D18 -> 2340.1581 | L45: =NPK!E18 -> 2113.6912 | M45: =NPK!F18 -> 2340.1581 | N45: =NPK!G18 -> 2264.6692 | O45: =NPK!H18 -> 2340.1581
A46: 5 | B46: PLATING | C46: =SUM(D46:O46) -> 29700.06 | D46: =NPK!I19 -> 2441.1008 | E46: =NPK!J19 -> 2522.4708 | F46: =NPK!K19 -> 2522.4708 | G46: =NPK!L19 -> 2441.1008 | H46: =NPK!M19 -> 2522.4708 | I46: =NPK!N19 -> 2441.1008 | J46: =NPK!O19 -> 2522.4708 | K46: =NPK!D19 -> 2522.4708 | L46: =NPK!E19 -> 2278.3608 | M46: =NPK!F19 -> 2522.4708 | N46: =NPK!G19 -> 2441.1008 | O46: =NPK!H19 -> 2522.4708
B47: TOTAL MANUFACTRING | C47: =C36+C38+C43+C45+C46 -> 839191.96 | D47: =D36+D38+D43+D45+D46 -> 68974.682 | E47: =E36+E38+E43+E45+E46 -> 71273.838 | F47: =F36+F38+F43+F45+F46 -> 71273.838 | G47: =G36+G38+G43+G45+G46 -> 68974.682 | H47: =H36+H38+H43+H45+H46 -> 71273.838 | I47: =I36+I38+I43+I45+I46 -> 68974.682 | J47: =J36+J38+J43+J45+J46 -> 71273.838 | ... O47: =O36+O38+O43+O45+O46 -> 71273.838
D48: =D25/D47 -> 0.96896786 | E48: =E25/E47 -> 0.90162466 | F48: =F25/F47 -> 0.89367644 | G48: =G25/G47 -> 0.85787637 | H48: =H25/H47 -> 0.8370603 | I48: =I25/I47 -> 0.8003154 | J48: =J25/J47 -> 0.5246806 | K48: =K25/K47 -> 0.44278519 | ... O48: =O25/O47 -> 0.13892896
...

Sheet SCB ACTUAL
A1: Planned | B1: 46028 | C1: 46060 | D1: 46092 | E1: 46124 | F1: 46156 | G1: 46188 | H1: 46220 | I1: 46252 | J1: 46284 | K1: 46316 | L1: 46348 | M1: 46380 | N1: Planned Hours Apr'26-Dec'26
A2: WELDING | B2: 51351.295 | C2: 47293 | D2: 51849 | E2: ='[62]SUMMARY-MFG'!D6 -> 52535 | F2: ='[62]SUMMARY-MFG'!E6 -> 52485 | G2: ='SUMMARY-CP'!D6 -> 49831.25 | H2: ='SUMMARY-CP'!E6 -> 49026.75 | I2: ='SUMMARY-CP'!F6 -> 47313.75 | J2: ='SUMMARY-CP'!G6 -> 44617.75 | K2: ='SUMMARY-CP'!H6 -> 44183.5 | L2: ='SUMMARY-CP'!I6 -> 41776.5 | M2: ='SUMMARY-CP'!J6 -> 24975 | N2: =SUM(G2:M2) -> 301724.5
A3: MACHINING | B3: 7519.22 | C3: 8153 | D3: 9028 | E3: ='[62]SUMMARY-MFG'!D12 -> 8947 | F3: ='[62]SUMMARY-MFG'!E12 -> 9129 | G3: ='SUMMARY-CP'!D12 -> 8475 | H3: ='SUMMARY-CP'!E12 -> 6792.5 | I3: ='SUMMARY-CP'!F12 -> 8144 | J3: ='SUMMARY-CP'!G12 -> 6540 | K3: ='SUMMARY-CP'!H12 -> 7635 | L3: ='SUMMARY-CP'!I12 -> 6550 | M3: ='SUMMARY-CP'!J12 -> 5756 | N3: =SUM(G3:M3) -> 49892.5
A4: ASSEMBLY | B4: 4945.01 | C4: 5159 | D4: 5700 | E4: ='[62]SUMMARY-MFG'!D20 -> 5686 | F4: ='[62]SUMMARY-MFG'!E20 -> 5630 | G4: ='SUMMARY-CP'!D20 -> 5428 | H4: ='SUMMARY-CP'!E20 -> 5543 | I4: ='SUMMARY-CP'!F20 -> 5538 | J4: ='SUMMARY-CP'!G20 -> 5614 | K4: ='SUMMARY-CP'!H20 -> 5542 | L4: ='SUMMARY-CP'!I20 -> 4785 | M4: ='SUMMARY-CP'!J20 -> 4765 | N4: =SUM(G4:M4) -> 37215
A5: ROLL REFURBISHMENT | B5: 2765.02 | C5: 2200 | D5: 1600 | E5: ='[62]SUMMARY-MFG'!D22 -> 1600 | F5: ='[62]SUMMARY-MFG'!E22 -> 1500 | G5: ='SUMMARY-CP'!D22 -> 1800 | H5: ='SUMMARY-CP'!E22 -> 1600 | I5: ='SUMMARY-CP'!F22 -> 1500 | J5: ='SUMMARY-CP'!G22 -> 1400 | K5: ='SUMMARY-CP'!H22 -> 1300 | L5: ='SUMMARY-CP'!I22 -> 1200 | M5: ='SUMMARY-CP'!J22 -> 1100 | N5: =SUM(G5:M5) -> 9900
A6: PLATING | B6: 4021 | C6: 2522 | D6: 2200 | E6: ='[62]SUMMARY-MFG'!D23 -> 1300 | F6: ='[62]SUMMARY-MFG'!E23 -> 1300 | G6: ='SUMMARY-CP'!D23 -> 1300 | H6: ='SUMMARY-CP'!E23 -> 1300 | I6: ='SUMMARY-CP'!F23 -> 1200 | J6: ='SUMMARY-CP'!G23 -> 1000 | K6: ='SUMMARY-CP'!H23 -> 1000 | L6: ='SUMMARY-CP'!I23 -> 890 | M6: ='SUMMARY-CP'!J23 -> 800 | N6: =SUM(G6:M6) -> 7490
A7: TOTAL | B7: =SUM(B2:B6) -> 70601.545 | C7: =SUM(C2:C6) -> 65327 | D7: =SUM(D2:D6) -> 70377 | E7: =SUM(E2:E6) -> 70068 | F7: =SUM(F2:F6) -> 70044 | G7: =SUM(G2:G6) -> 66834.25 | H7: =SUM(H2:H6) -> 64262.25 | I7: =SUM(I2:I6) -> 63695.75 | ... M7: =SUM(M2:M6) -> 37396 | N7: =SUM(G7:M7) -> 406222
A9: NPK Capacity | B9: 46028 | C9: 46060 | D9: 46092 | E9: 46124 | F9: 46156 | G9: 46188 | H9: 46220 | I9: 46252 | J9: 46284 | K9: 46316 | L9: 46348 | M9: 46380 | N9: Planned Hours Apr'26-Dec'26
A10: WELDING | B10: =[62]NPK!D9 -> 51778.145 | C10: 46767 | D10: 51778.145 | E10: ='[62]SUMMARY-MFG'!D36 -> 50107.882 | F10: ='[62]SUMMARY-MFG'!E36 -> 51778.145 | G10: ='SUMMARY-CP'!D36 -> 50107.882 | H10: ='SUMMARY-CP'!E36 -> 51778.145 | I10: ='SUMMARY-CP'!F36 -> 51778.145 | J10: ='SUMMARY-CP'!G36 -> 50107.882 | K10: ='SUMMARY-CP'!H36 -> 51778.145 | L10: ='SUMMARY-CP'!I36 -> 50107.882 | M10: ='SUMMARY-CP'!J36 -> 51778.145 | N10: =SUM(G10:M10) -> 357436.23
A11: MACHINING | B11: =[62]NPK!D11 -> 9028.7312 | C11: 8155 | D11: 9028.7312 | E11: ='[62]SUMMARY-MFG'!D38 -> 8737.4818 | F11: ='[62]SUMMARY-MFG'!E38 -> 9028.7312 | G11: ='SUMMARY-CP'!D38 -> 8737.4818 | H11: ='SUMMARY-CP'!E38 -> 9028.7312 | I11: ='SUMMARY-CP'!F38 -> 9028.7312 | J11: ='SUMMARY-CP'!G38 -> 8737.4818 | K11: ='SUMMARY-CP'!H38 -> 9028.7312 | L11: ='SUMMARY-CP'!I38 -> 8737.4818 | M11: ='SUMMARY-CP'!J38 -> 9028.7312 | N11: =SUM(G11:M11) -> 62327.37
A12: ASSEMBLY | B12: =[62]NPK!D16 -> 5604.3329 | C12: 5062 | D12: 5604.3329 | E12: ='[62]SUMMARY-MFG'!D43 -> 5423.5479 | F12: ='[62]SUMMARY-MFG'!E43 -> 5604.3329 | G12: ='SUMMARY-CP'!D43 -> 5423.5479 | H12: ='SUMMARY-CP'!E43 -> 5604.3329 | I12: ='SUMMARY-CP'!F43 -> 5604.3329 | J12: ='SUMMARY-CP'!G43 -> 5423.5479 | K12: ='SUMMARY-CP'!H43 -> 5604.3329 | L12: ='SUMMARY-CP'!I43 -> 5423.5479 | M12: ='SUMMARY-CP'!J43 -> 5604.3329 | N12: =SUM(G12:M12) -> 38687.975
A13: ROLL REFURBISHMENT | B13: =[62]NPK!D18 -> 2340.1581 | C13: 2340 | D13: 2340.1581 | E13: ='[62]SUMMARY-MFG'!D45 -> 2340.1581 | F13: ='[62]SUMMARY-MFG'!E45 -> 2264.6692 | G13: ='SUMMARY-CP'!D45 -> 2264.6692 | H13: ='SUMMARY-CP'!E45 -> 2340.1581 | I13: ='SUMMARY-CP'!F45 -> 2340.1581 | J13: ='SUMMARY-CP'!G45 -> 2264.6692 | K13: ='SUMMARY-CP'!H45 -> 2340.1581 | L13: ='SUMMARY-CP'!I45 -> 2264.6692 | M13: ='SUMMARY-CP'!J45 -> 2340.1581 | N13: =SUM(G13:M13) -> 16154.64
A14: PLATING | B14: =[62]NPK!D19 -> 2522.4708 | C14: 2522 | D14: 2522.4708 | E14: ='[62]SUMMARY-MFG'!D46 -> 2522.4708 | F14: ='[62]SUMMARY-MFG'!E46 -> 2441.1008 | G14: ='SUMMARY-CP'!D46 -> 2441.1008 | H14: ='SUMMARY-CP'!E46 -> 2522.4708 | I14: ='SUMMARY-CP'!F46 -> 2522.4708 | J14: ='SUMMARY-CP'!G46 -> 2441.1008 | K14: ='SUMMARY-CP'!H46 -> 2522.4708 | L14: ='SUMMARY-CP'!I46 -> 2441.1008 | M14: ='SUMMARY-CP'!J46 -> 2522.4708 | N14: =SUM(G14:M14) -> 17413.186
A15: TOTAL | B15: =SUM(B10:B14) -> 71273.838 | C15: =SUM(C10:C14) -> 64846 | D15: =SUM(D10:D14) -> 71273.838 | E15: =SUM(E10:E14) -> 69131.541 | F15: =SUM(F10:F14) -> 71116.979 | G15: =SUM(G10:G14) -> 68974.682 | H15: =SUM(H10:H14) -> 71273.838 | I15: =SUM(I10:I14) -> 71273.838 | ... M15: =SUM(M10:M14) -> 71273.838 | N15: =SUM(G15:M15) -> 492019.4
A17: Planned Hours | B17: 46028 | C17: 46060 | D17: 46092 | E17: 46124 | F17: 46156 | G17: 46188 | H17: 46220 | I17: 46252 | J17: 46284 | K17: 46316 | L17: 46348 | M17: 46380 | N17: Planned Hours Apr'26-Dec'26
A18: WELDING | B18: =B2/1000 -> 51.351295 | C18: =C2/1000 -> 47.293 | D18: =D2/1000 -> 51.849 | E18: =E2/1000 -> 52.535 | F18: =F2/1000 -> 52.485 | G18: =G2/1000 -> 49.83125 | H18: =H2/1000 -> 49.02675 | I18: =I2/1000 -> 47.31375 | ... M18: =M2/1000 -> 24.975 | N18: =SUM(G18:M18) -> 301.7245
A19: MACHINING | B19: =B3/1000 -> 7.51922 | C19: =C3/1000 -> 8.153 | D19: =D3/1000 -> 9.028 | E19: =E3/1000 -> 8.947 | F19: =F3/1000 -> 9.129 | G19: =G3/1000 -> 8.475 | H19: =H3/1000 -> 6.7925 | I19: =I3/1000 -> 8.144 | ... M19: =M3/1000 -> 5.756 | N19: =SUM(G19:M19) -> 49.8925
A20: ASSEMBLY | B20: =B4/1000 -> 4.94501 | C20: =C4/1000 -> 5.159 | D20: =D4/1000 -> 5.7 | E20: =E4/1000 -> 5.686 | F20: =F4/1000 -> 5.63 | G20: =G4/1000 -> 5.428 | H20: =H4/1000 -> 5.543 | I20: =I4/1000 -> 5.538 | ... M20: =M4/1000 -> 4.765 | N20: =SUM(G20:M20) -> 37.215
A21: ROLL REFURBISHMENT | B21: =B5/1000 -> 2.76502 | C21: =C5/1000 -> 2.2 | D21: =D5/1000 -> 1.6 | E21: =E5/1000 -> 1.6 | F21: =F5/1000 -> 1.5 | G21: =G5/1000 -> 1.8 | H21: =H5/1000 -> 1.6 | I21: =I5/1000 -> 1.5 | ... M21: =M5/1000 -> 1.1 | N21: =SUM(G21:M21) -> 9.9
